{"timestamp": "2025-07-05T23:49:56.330990Z", "level": "ERROR", "logger": "adogent", "message": "Error logging test message", "module": "main", "function": "lifespan", "line": 34, "thread": 281473536356384, "thread_name": "MainThread", "process": 10, "service": "adogent-backend", "environment": "development"}
{"timestamp": "2025-07-05T23:49:56.336251Z", "level": "ERROR", "logger": "adogent", "message": "Error logging test message", "module": "main", "function": "lifespan", "line": 34, "thread": 281473256669216, "thread_name": "MainThread", "process": 11, "service": "adogent-backend", "environment": "development"}
{"timestamp": "2025-07-05T23:49:56.336937Z", "level": "ERROR", "logger": "adogent", "message": "Error logging test message", "module": "main", "function": "lifespan", "line": 34, "thread": 281473357934624, "thread_name": "MainThread", "process": 13, "service": "adogent-backend", "environment": "development"}
{"timestamp": "2025-07-05T23:49:56.337023Z", "level": "ERROR", "logger": "adogent", "message": "Error logging test message", "module": "main", "function": "lifespan", "line": 34, "thread": 281473404743712, "thread_name": "MainThread", "process": 12, "service": "adogent-backend", "environment": "development"}
{"timestamp": "2025-07-05T23:51:56.605995Z", "level": "ERROR", "logger": "adogent", "message": "Registration error: object NoneType can't be used in 'await' expression", "module": "auth", "function": "register_user", "line": 119, "thread": 281473404743712, "thread_name": "MainThread", "process": 12, "service": "adogent-backend", "environment": "development"}
{"timestamp": "2025-07-06T00:04:17.044670Z", "level": "ERROR", "logger": "adogent", "message": "Error logging test message", "module": "main", "function": "lifespan", "line": 34, "thread": 281472878772256, "thread_name": "MainThread", "process": 10, "service": "adogent-backend", "environment": "development"}
{"timestamp": "2025-07-06T00:04:17.044766Z", "level": "ERROR", "logger": "adogent", "message": "Error logging test message", "module": "main", "function": "lifespan", "line": 34, "thread": 281473250316320, "thread_name": "MainThread", "process": 12, "service": "adogent-backend", "environment": "development"}
{"timestamp": "2025-07-06T00:04:17.044774Z", "level": "ERROR", "logger": "adogent", "message": "Error logging test message", "module": "main", "function": "lifespan", "line": 34, "thread": 281473839714336, "thread_name": "MainThread", "process": 11, "service": "adogent-backend", "environment": "development"}
{"timestamp": "2025-07-06T00:04:17.047360Z", "level": "ERROR", "logger": "adogent", "message": "Error logging test message", "module": "main", "function": "lifespan", "line": 34, "thread": 281473649786912, "thread_name": "MainThread", "process": 13, "service": "adogent-backend", "environment": "development"}
{"timestamp": "2025-07-06T00:04:25.639074Z", "level": "ERROR", "logger": "adogent", "message": "Error: property 'is_active' of 'User' object has no setter", "module": "log", "function": "log_error", "line": 271, "thread": 281472878772256, "thread_name": "MainThread", "process": 10, "service": "adogent-backend", "environment": "development", "exception": {"type": "AttributeError", "message": "property 'is_active' of 'User' object has no setter", "traceback": "Traceback (most recent call last):\n  File \"/usr/app/app/services/auth_service.py\", line 91, in register_user\n    new_user = User(\n               ^^^^^\n  File \"<string>\", line 4, in __init__\n  File \"/usr/local/lib/python3.12/site-packages/sqlalchemy/orm/state.py\", line 571, in _initialize_instance\n    with util.safe_reraise():\n         ^^^^^^^^^^^^^^^^^^^\n  File \"/usr/local/lib/python3.12/site-packages/sqlalchemy/util/langhelpers.py\", line 146, in __exit__\n    raise exc_value.with_traceback(exc_tb)\n  File \"/usr/local/lib/python3.12/site-packages/sqlalchemy/orm/state.py\", line 569, in _initialize_instance\n    manager.original_init(*mixed[1:], **kwargs)\n  File \"/usr/local/lib/python3.12/site-packages/sqlalchemy/orm/decl_base.py\", line 2180, in _declarative_constructor\n    setattr(self, k, kwargs[k])\nAttributeError: property 'is_active' of 'User' object has no setter"}}
{"timestamp": "2025-07-06T00:04:25.639566Z", "level": "ERROR", "logger": "adogent", "message": "Registration error: property 'is_active' of 'User' object has no setter", "module": "auth", "function": "register_user", "line": 119, "thread": 281472878772256, "thread_name": "MainThread", "process": 10, "service": "adogent-backend", "environment": "development"}
{"timestamp": "2025-07-06T00:20:16.195301Z", "level": "ERROR", "logger": "adogent", "message": "Error logging test message", "module": "main", "function": "lifespan", "line": 34, "thread": 281473577979936, "thread_name": "MainThread", "process": 10, "service": "adogent-backend", "environment": "development"}
{"timestamp": "2025-07-06T00:20:16.195335Z", "level": "ERROR", "logger": "adogent", "message": "Error logging test message", "module": "main", "function": "lifespan", "line": 34, "thread": 281473602158624, "thread_name": "MainThread", "process": 13, "service": "adogent-backend", "environment": "development"}
{"timestamp": "2025-07-06T00:20:16.195347Z", "level": "ERROR", "logger": "adogent", "message": "Error logging test message", "module": "main", "function": "lifespan", "line": 34, "thread": 281473043714080, "thread_name": "MainThread", "process": 11, "service": "adogent-backend", "environment": "development"}
{"timestamp": "2025-07-06T00:20:16.195365Z", "level": "ERROR", "logger": "adogent", "message": "Error logging test message", "module": "main", "function": "lifespan", "line": 34, "thread": 281473057742880, "thread_name": "MainThread", "process": 12, "service": "adogent-backend", "environment": "development"}
{"timestamp": "2025-07-06T00:21:04.532730Z", "level": "ERROR", "logger": "adogent", "message": "Error: 'UserCreateRequest' object has no attribute 'allow_voice_data_storage'", "module": "log", "function": "log_error", "line": 331, "thread": 281473043714080, "thread_name": "MainThread", "process": 11, "service": "adogent-backend", "environment": "development", "exception": {"type": "AttributeError", "message": "'UserCreateRequest' object has no attribute 'allow_voice_data_storage'", "traceback": "Traceback (most recent call last):\n  File \"/usr/app/app/services/auth_service.py\", line 103, in register_user\n    allow_voice_data_storage=user_data.allow_voice_data_storage,\n                             ^^^^^^^^^^^^^^^^^^^^^^^^^^^^^^^^^^\n  File \"/usr/local/lib/python3.12/site-packages/pydantic/main.py\", line 984, in __getattr__\n    raise AttributeError(f'{type(self).__name__!r} object has no attribute {item!r}')\nAttributeError: 'UserCreateRequest' object has no attribute 'allow_voice_data_storage'"}}
{"timestamp": "2025-07-06T00:21:04.535420Z", "level": "ERROR", "logger": "adogent", "message": "Registration error: 'UserCreateRequest' object has no attribute 'allow_voice_data_storage'", "module": "auth", "function": "register_user", "line": 119, "thread": 281473043714080, "thread_name": "MainThread", "process": 11, "service": "adogent-backend", "environment": "development"}
{"timestamp": "2025-07-06T00:33:53.166327Z", "level": "ERROR", "logger": "adogent", "message": "Error logging test message", "module": "main", "function": "lifespan", "line": 34, "thread": 281473118662688, "thread_name": "MainThread", "process": 13, "service": "adogent-backend", "environment": "development"}
{"timestamp": "2025-07-06T00:33:53.166362Z", "level": "ERROR", "logger": "adogent", "message": "Error logging test message", "module": "main", "function": "lifespan", "line": 34, "thread": 281473888378912, "thread_name": "MainThread", "process": 12, "service": "adogent-backend", "environment": "development"}
{"timestamp": "2025-07-06T00:33:53.166384Z", "level": "ERROR", "logger": "adogent", "message": "Error logging test message", "module": "main", "function": "lifespan", "line": 34, "thread": 281472900792352, "thread_name": "MainThread", "process": 11, "service": "adogent-backend", "environment": "development"}
{"timestamp": "2025-07-06T00:33:53.166393Z", "level": "ERROR", "logger": "adogent", "message": "Error logging test message", "module": "main", "function": "lifespan", "line": 34, "thread": 281473685872672, "thread_name": "MainThread", "process": 10, "service": "adogent-backend", "environment": "development"}
{"timestamp": "2025-07-06T00:35:10.278010Z", "level": "ERROR", "logger": "adogent", "message": "Error: 'User' object has no attribute 'is_verified'", "module": "log", "function": "log_error", "line": 331, "thread": 281473118662688, "thread_name": "MainThread", "process": 13, "service": "adogent-backend", "environment": "development", "exception": {"type": "AttributeError", "message": "'User' object has no attribute 'is_verified'", "traceback": "Traceback (most recent call last):\n  File \"/usr/app/app/services/auth_service.py\", line 115, in register_user\n    is_verified=new_user.is_verified\n                ^^^^^^^^^^^^^^^^^^^^\nAttributeError: 'User' object has no attribute 'is_verified'"}}
{"timestamp": "2025-07-06T00:35:10.283193Z", "level": "ERROR", "logger": "adogent", "message": "Registration error: 'User' object has no attribute 'is_verified'", "module": "auth", "function": "register_user", "line": 119, "thread": 281473118662688, "thread_name": "MainThread", "process": 13, "service": "adogent-backend", "environment": "development"}
{"timestamp": "2025-07-06T00:40:28.433846Z", "level": "ERROR", "logger": "adogent", "message": "Error logging test message", "module": "main", "function": "lifespan", "line": 34, "thread": 281473278156832, "thread_name": "MainThread", "process": 13, "service": "adogent-backend", "environment": "development"}
{"timestamp": "2025-07-06T00:40:28.434640Z", "level": "ERROR", "logger": "adogent", "message": "Error logging test message", "module": "main", "function": "lifespan", "line": 34, "thread": 281472893833248, "thread_name": "MainThread", "process": 11, "service": "adogent-backend", "environment": "development"}
{"timestamp": "2025-07-06T00:40:28.438931Z", "level": "ERROR", "logger": "adogent", "message": "Error logging test message", "module": "main", "function": "lifespan", "line": 34, "thread": 281473298972704, "thread_name": "MainThread", "process": 10, "service": "adogent-backend", "environment": "development"}
{"timestamp": "2025-07-06T00:40:28.442109Z", "level": "ERROR", "logger": "adogent", "message": "Error logging test message", "module": "main", "function": "lifespan", "line": 34, "thread": 281473824448544, "thread_name": "MainThread", "process": 12, "service": "adogent-backend", "environment": "development"}
{"timestamp": "2025-07-06T00:40:45.701306Z", "level": "ERROR", "logger": "adogent", "message": "Error: 'last_used' is an invalid keyword argument for UserSession", "module": "log", "function": "log_error", "line": 331, "thread": 281472893833248, "thread_name": "MainThread", "process": 11, "service": "adogent-backend", "environment": "development", "exception": {"type": "TypeError", "message": "'last_used' is an invalid keyword argument for UserSession", "traceback": "Traceback (most recent call last):\n  File \"/usr/app/app/services/auth_service.py\", line 120, in register_user\n    await self._create_user_session(\n  File \"/usr/app/app/services/auth_service.py\", line 401, in _create_user_session\n    session = UserSession(\n              ^^^^^^^^^^^^\n  File \"<string>\", line 4, in __init__\n  File \"/usr/local/lib/python3.12/site-packages/sqlalchemy/orm/state.py\", line 571, in _initialize_instance\n    with util.safe_reraise():\n         ^^^^^^^^^^^^^^^^^^^\n  File \"/usr/local/lib/python3.12/site-packages/sqlalchemy/util/langhelpers.py\", line 146, in __exit__\n    raise exc_value.with_traceback(exc_tb)\n  File \"/usr/local/lib/python3.12/site-packages/sqlalchemy/orm/state.py\", line 569, in _initialize_instance\n    manager.original_init(*mixed[1:], **kwargs)\n  File \"/usr/local/lib/python3.12/site-packages/sqlalchemy/orm/decl_base.py\", line 2177, in _declarative_constructor\n    raise TypeError(\nTypeError: 'last_used' is an invalid keyword argument for UserSession"}}
{"timestamp": "2025-07-06T00:40:45.701804Z", "level": "ERROR", "logger": "adogent", "message": "Registration error: 'last_used' is an invalid keyword argument for UserSession", "module": "auth", "function": "register_user", "line": 119, "thread": 281472893833248, "thread_name": "MainThread", "process": 11, "service": "adogent-backend", "environment": "development"}
{"timestamp": "2025-07-06T00:46:25.458359Z", "level": "ERROR", "logger": "adogent", "message": "Error logging test message", "module": "main", "function": "lifespan", "line": 34, "thread": 281473846640672, "thread_name": "MainThread", "process": 13, "service": "adogent-backend", "environment": "development"}
{"timestamp": "2025-07-06T00:46:25.458459Z", "level": "ERROR", "logger": "adogent", "message": "Error logging test message", "module": "main", "function": "lifespan", "line": 34, "thread": 281473671389216, "thread_name": "MainThread", "process": 12, "service": "adogent-backend", "environment": "development"}
{"timestamp": "2025-07-06T00:46:25.464098Z", "level": "ERROR", "logger": "adogent", "message": "Error logging test message", "module": "main", "function": "lifespan", "line": 34, "thread": 281473727115296, "thread_name": "MainThread", "process": 11, "service": "adogent-backend", "environment": "development"}
{"timestamp": "2025-07-06T00:46:25.464226Z", "level": "ERROR", "logger": "adogent", "message": "Error logging test message", "module": "main", "function": "lifespan", "line": 34, "thread": 281472873054240, "thread_name": "MainThread", "process": 10, "service": "adogent-backend", "environment": "development"}
{"timestamp": "2025-07-06T00:46:43.362034Z", "level": "ERROR", "logger": "adogent", "message": "Error: (sqlalchemy.dialects.postgresql.asyncpg.Error) <class 'asyncpg.exceptions.DataError'>: invalid input for query argument $4: {} (expected str, got dict)\n[SQL: INSERT INTO user_sessions (user_id, session_token, refresh_token, device_info, ip_address, user_agent, is_active, is_revoked, expires_at, last_accessed, revoked_at, id, created_at, updated_at, deleted_at, is_deleted) VALUES ($1::UUID, $2::VARCHAR, $3::VARCHAR, $4::VARCHAR, $5::VARCHAR, $6::VARCHAR, $7::BOOLEAN, $8::BOOLEAN, $9::TIMESTAMP WITHOUT TIME ZONE, now(), $10::TIMESTAMP WITHOUT TIME ZONE, $11::UUID, now(), now(), $12::TIMESTAMP WITHOUT TIME ZONE, $13::BOOLEAN) RETURNING user_sessions.last_accessed, user_sessions.created_at, user_sessions.updated_at]\n[parameters: (UUID('0ca56c62-3f93-440c-95fa-e155bab28248'), None, 'eyJhbGciOiJIUzI1NiIsInR5cCI6IkpXVCJ9.eyJzdWIiOiIwY2E1NmM2Mi0zZjkzLTQ0MGMtOTVmYS1lMTU1YmFiMjgyNDgiLCJ0eXBlIjoicmVmcmVzaCIsImp0aSI6ImltdTFhczhmcjZSQWVZSWhZMGxmQ1U2ZWJsN3ZpVEVoMmhFSXBySkZKRmciLCJleHAiOjE3NTIzNjc2MDMsImlhdCI6MTc1MTc2MjgwM30.8WEf5vO44aHBK0xGSmFwXBWT5jiCioQ0VDjvajweq1o', {}, None, None, True, False, datetime.datetime(2025, 7, 13, 0, 46, 43, 347591), None, UUID('8b3c7277-4ab1-48a4-8eeb-94bbbf4be35e'), None, False)]\n(Background on this error at: https://sqlalche.me/e/20/dbapi)", "module": "log", "function": "log_error", "line": 331, "thread": 281472873054240, "thread_name": "MainThread", "process": 10, "service": "adogent-backend", "environment": "development", "exception": {"type": "DBAPIError", "message": "(sqlalchemy.dialects.postgresql.asyncpg.Error) <class 'asyncpg.exceptions.DataError'>: invalid input for query argument $4: {} (expected str, got dict)\n[SQL: INSERT INTO user_sessions (user_id, session_token, refresh_token, device_info, ip_address, user_agent, is_active, is_revoked, expires_at, last_accessed, revoked_at, id, created_at, updated_at, deleted_at, is_deleted) VALUES ($1::UUID, $2::VARCHAR, $3::VARCHAR, $4::VARCHAR, $5::VARCHAR, $6::VARCHAR, $7::BOOLEAN, $8::BOOLEAN, $9::TIMESTAMP WITHOUT TIME ZONE, now(), $10::TIMESTAMP WITHOUT TIME ZONE, $11::UUID, now(), now(), $12::TIMESTAMP WITHOUT TIME ZONE, $13::BOOLEAN) RETURNING user_sessions.last_accessed, user_sessions.created_at, user_sessions.updated_at]\n[parameters: (UUID('0ca56c62-3f93-440c-95fa-e155bab28248'), None, 'eyJhbGciOiJIUzI1NiIsInR5cCI6IkpXVCJ9.eyJzdWIiOiIwY2E1NmM2Mi0zZjkzLTQ0MGMtOTVmYS1lMTU1YmFiMjgyNDgiLCJ0eXBlIjoicmVmcmVzaCIsImp0aSI6ImltdTFhczhmcjZSQWVZSWhZMGxmQ1U2ZWJsN3ZpVEVoMmhFSXBySkZKRmciLCJleHAiOjE3NTIzNjc2MDMsImlhdCI6MTc1MTc2MjgwM30.8WEf5vO44aHBK0xGSmFwXBWT5jiCioQ0VDjvajweq1o', {}, None, None, True, False, datetime.datetime(2025, 7, 13, 0, 46, 43, 347591), None, UUID('8b3c7277-4ab1-48a4-8eeb-94bbbf4be35e'), None, False)]\n(Background on this error at: https://sqlalche.me/e/20/dbapi)", "traceback": "Traceback (most recent call last):\n  File \"asyncpg/protocol/prepared_stmt.pyx\", line 175, in asyncpg.protocol.protocol.PreparedStatementState._encode_bind_msg\n  File \"asyncpg/protocol/codecs/base.pyx\", line 227, in asyncpg.protocol.protocol.Codec.encode\n  File \"asyncpg/protocol/codecs/base.pyx\", line 129, in asyncpg.protocol.protocol.Codec.encode_scalar\n  File \"asyncpg/pgproto/./codecs/text.pyx\", line 29, in asyncpg.pgproto.pgproto.text_encode\n  File \"asyncpg/pgproto/./codecs/text.pyx\", line 12, in asyncpg.pgproto.pgproto.as_pg_string_and_size\nTypeError: expected str, got dict\n\nThe above exception was the direct cause of the following exception:\n\nTraceback (most recent call last):\n  File \"/usr/local/lib/python3.12/site-packages/sqlalchemy/dialects/postgresql/asyncpg.py\", line 534, in _prepare_and_execute\n    self._rows = deque(await prepared_stmt.fetch(*parameters))\n                       ^^^^^^^^^^^^^^^^^^^^^^^^^^^^^^^^^^^^^^\n  File \"/usr/local/lib/python3.12/site-packages/asyncpg/prepared_stmt.py\", line 176, in fetch\n    data = await self.__bind_execute(args, 0, timeout)\n           ^^^^^^^^^^^^^^^^^^^^^^^^^^^^^^^^^^^^^^^^^^^\n  File \"/usr/local/lib/python3.12/site-packages/asyncpg/prepared_stmt.py\", line 267, in __bind_execute\n    data, status, _ = await self.__do_execute(\n                      ^^^^^^^^^^^^^^^^^^^^^^^^\n  File \"/usr/local/lib/python3.12/site-packages/asyncpg/prepared_stmt.py\", line 256, in __do_execute\n    return await executor(protocol)\n           ^^^^^^^^^^^^^^^^^^^^^^^^\n  File \"asyncpg/protocol/protocol.pyx\", line 185, in bind_execute\n  File \"asyncpg/protocol/prepared_stmt.pyx\", line 204, in asyncpg.protocol.protocol.PreparedStatementState._encode_bind_msg\nasyncpg.exceptions.DataError: invalid input for query argument $4: {} (expected str, got dict)\n\nThe above exception was the direct cause of the following exception:\n\nTraceback (most recent call last):\n  File \"/usr/local/lib/python3.12/site-packages/sqlalchemy/engine/base.py\", line 1967, in _exec_single_context\n    self.dialect.do_execute(\n  File \"/usr/local/lib/python3.12/site-packages/sqlalchemy/engine/default.py\", line 941, in do_execute\n    cursor.execute(statement, parameters)\n  File \"/usr/local/lib/python3.12/site-packages/sqlalchemy/dialects/postgresql/asyncpg.py\", line 568, in execute\n    self._adapt_connection.await_(\n  File \"/usr/local/lib/python3.12/site-packages/sqlalchemy/util/_concurrency_py3k.py\", line 132, in await_only\n    return current.parent.switch(awaitable)  # type: ignore[no-any-return,attr-defined] # noqa: E501\n           ^^^^^^^^^^^^^^^^^^^^^^^^^^^^^^^^\n  File \"/usr/local/lib/python3.12/site-packages/sqlalchemy/util/_concurrency_py3k.py\", line 196, in greenlet_spawn\n    value = await result\n            ^^^^^^^^^^^^\n  File \"/usr/local/lib/python3.12/site-packages/sqlalchemy/dialects/postgresql/asyncpg.py\", line 546, in _prepare_and_execute\n    self._handle_exception(error)\n  File \"/usr/local/lib/python3.12/site-packages/sqlalchemy/dialects/postgresql/asyncpg.py\", line 497, in _handle_exception\n    self._adapt_connection._handle_exception(error)\n  File \"/usr/local/lib/python3.12/site-packages/sqlalchemy/dialects/postgresql/asyncpg.py\", line 780, in _handle_exception\n    raise translated_error from error\nsqlalchemy.dialects.postgresql.asyncpg.AsyncAdapt_asyncpg_dbapi.Error: <class 'asyncpg.exceptions.DataError'>: invalid input for query argument $4: {} (expected str, got dict)\n\nThe above exception was the direct cause of the following exception:\n\nTraceback (most recent call last):\n  File \"/usr/app/app/services/auth_service.py\", line 126, in register_user\n    await self.db.commit()\n  File \"/usr/local/lib/python3.12/site-packages/sqlalchemy/ext/asyncio/session.py\", line 1009, in commit\n    await greenlet_spawn(self.sync_session.commit)\n  File \"/usr/local/lib/python3.12/site-packages/sqlalchemy/util/_concurrency_py3k.py\", line 203, in greenlet_spawn\n    result = context.switch(value)\n             ^^^^^^^^^^^^^^^^^^^^^\n  File \"/usr/local/lib/python3.12/site-packages/sqlalchemy/orm/session.py\", line 2028, in commit\n    trans.commit(_to_root=True)\n  File \"<string>\", line 2, in commit\n  File \"/usr/local/lib/python3.12/site-packages/sqlalchemy/orm/state_changes.py\", line 139, in _go\n    ret_value = fn(self, *arg, **kw)\n                ^^^^^^^^^^^^^^^^^^^^\n  File \"/usr/local/lib/python3.12/site-packages/sqlalchemy/orm/session.py\", line 1313, in commit\n    self._prepare_impl()\n  File \"<string>\", line 2, in _prepare_impl\n  File \"/usr/local/lib/python3.12/site-packages/sqlalchemy/orm/state_changes.py\", line 139, in _go\n    ret_value = fn(self, *arg, **kw)\n                ^^^^^^^^^^^^^^^^^^^^\n  File \"/usr/local/lib/python3.12/site-packages/sqlalchemy/orm/session.py\", line 1288, in _prepare_impl\n    self.session.flush()\n  File \"/usr/local/lib/python3.12/site-packages/sqlalchemy/orm/session.py\", line 4352, in flush\n    self._flush(objects)\n  File \"/usr/local/lib/python3.12/site-packages/sqlalchemy/orm/session.py\", line 4487, in _flush\n    with util.safe_reraise():\n         ^^^^^^^^^^^^^^^^^^^\n  File \"/usr/local/lib/python3.12/site-packages/sqlalchemy/util/langhelpers.py\", line 146, in __exit__\n    raise exc_value.with_traceback(exc_tb)\n  File \"/usr/local/lib/python3.12/site-packages/sqlalchemy/orm/session.py\", line 4448, in _flush\n    flush_context.execute()\n  File \"/usr/local/lib/python3.12/site-packages/sqlalchemy/orm/unitofwork.py\", line 466, in execute\n    rec.execute(self)\n  File \"/usr/local/lib/python3.12/site-packages/sqlalchemy/orm/unitofwork.py\", line 642, in execute\n    util.preloaded.orm_persistence.save_obj(\n  File \"/usr/local/lib/python3.12/site-packages/sqlalchemy/orm/persistence.py\", line 93, in save_obj\n    _emit_insert_statements(\n  File \"/usr/local/lib/python3.12/site-packages/sqlalchemy/orm/persistence.py\", line 1233, in _emit_insert_statements\n    result = connection.execute(\n             ^^^^^^^^^^^^^^^^^^^\n  File \"/usr/local/lib/python3.12/site-packages/sqlalchemy/engine/base.py\", line 1418, in execute\n    return meth(\n           ^^^^^\n  File \"/usr/local/lib/python3.12/site-packages/sqlalchemy/sql/elements.py\", line 515, in _execute_on_connection\n    return connection._execute_clauseelement(\n           ^^^^^^^^^^^^^^^^^^^^^^^^^^^^^^^^^^\n  File \"/usr/local/lib/python3.12/site-packages/sqlalchemy/engine/base.py\", line 1640, in _execute_clauseelement\n    ret = self._execute_context(\n          ^^^^^^^^^^^^^^^^^^^^^^\n  File \"/usr/local/lib/python3.12/site-packages/sqlalchemy/engine/base.py\", line 1846, in _execute_context\n    return self._exec_single_context(\n           ^^^^^^^^^^^^^^^^^^^^^^^^^^\n  File \"/usr/local/lib/python3.12/site-packages/sqlalchemy/engine/base.py\", line 1986, in _exec_single_context\n    self._handle_dbapi_exception(\n  File \"/usr/local/lib/python3.12/site-packages/sqlalchemy/engine/base.py\", line 2355, in _handle_dbapi_exception\n    raise sqlalchemy_exception.with_traceback(exc_info[2]) from e\n  File \"/usr/local/lib/python3.12/site-packages/sqlalchemy/engine/base.py\", line 1967, in _exec_single_context\n    self.dialect.do_execute(\n  File \"/usr/local/lib/python3.12/site-packages/sqlalchemy/engine/default.py\", line 941, in do_execute\n    cursor.execute(statement, parameters)\n  File \"/usr/local/lib/python3.12/site-packages/sqlalchemy/dialects/postgresql/asyncpg.py\", line 568, in execute\n    self._adapt_connection.await_(\n  File \"/usr/local/lib/python3.12/site-packages/sqlalchemy/util/_concurrency_py3k.py\", line 132, in await_only\n    return current.parent.switch(awaitable)  # type: ignore[no-any-return,attr-defined] # noqa: E501\n           ^^^^^^^^^^^^^^^^^^^^^^^^^^^^^^^^\n  File \"/usr/local/lib/python3.12/site-packages/sqlalchemy/util/_concurrency_py3k.py\", line 196, in greenlet_spawn\n    value = await result\n            ^^^^^^^^^^^^\n  File \"/usr/local/lib/python3.12/site-packages/sqlalchemy/dialects/postgresql/asyncpg.py\", line 546, in _prepare_and_execute\n    self._handle_exception(error)\n  File \"/usr/local/lib/python3.12/site-packages/sqlalchemy/dialects/postgresql/asyncpg.py\", line 497, in _handle_exception\n    self._adapt_connection._handle_exception(error)\n  File \"/usr/local/lib/python3.12/site-packages/sqlalchemy/dialects/postgresql/asyncpg.py\", line 780, in _handle_exception\n    raise translated_error from error\nsqlalchemy.exc.DBAPIError: (sqlalchemy.dialects.postgresql.asyncpg.Error) <class 'asyncpg.exceptions.DataError'>: invalid input for query argument $4: {} (expected str, got dict)\n[SQL: INSERT INTO user_sessions (user_id, session_token, refresh_token, device_info, ip_address, user_agent, is_active, is_revoked, expires_at, last_accessed, revoked_at, id, created_at, updated_at, deleted_at, is_deleted) VALUES ($1::UUID, $2::VARCHAR, $3::VARCHAR, $4::VARCHAR, $5::VARCHAR, $6::VARCHAR, $7::BOOLEAN, $8::BOOLEAN, $9::TIMESTAMP WITHOUT TIME ZONE, now(), $10::TIMESTAMP WITHOUT TIME ZONE, $11::UUID, now(), now(), $12::TIMESTAMP WITHOUT TIME ZONE, $13::BOOLEAN) RETURNING user_sessions.last_accessed, user_sessions.created_at, user_sessions.updated_at]\n[parameters: (UUID('0ca56c62-3f93-440c-95fa-e155bab28248'), None, 'eyJhbGciOiJIUzI1NiIsInR5cCI6IkpXVCJ9.eyJzdWIiOiIwY2E1NmM2Mi0zZjkzLTQ0MGMtOTVmYS1lMTU1YmFiMjgyNDgiLCJ0eXBlIjoicmVmcmVzaCIsImp0aSI6ImltdTFhczhmcjZSQWVZSWhZMGxmQ1U2ZWJsN3ZpVEVoMmhFSXBySkZKRmciLCJleHAiOjE3NTIzNjc2MDMsImlhdCI6MTc1MTc2MjgwM30.8WEf5vO44aHBK0xGSmFwXBWT5jiCioQ0VDjvajweq1o', {}, None, None, True, False, datetime.datetime(2025, 7, 13, 0, 46, 43, 347591), None, UUID('8b3c7277-4ab1-48a4-8eeb-94bbbf4be35e'), None, False)]\n(Background on this error at: https://sqlalche.me/e/20/dbapi)"}}
{"timestamp": "2025-07-06T00:46:43.363787Z", "level": "ERROR", "logger": "adogent", "message": "Registration error: (sqlalchemy.dialects.postgresql.asyncpg.Error) <class 'asyncpg.exceptions.DataError'>: invalid input for query argument $4: {} (expected str, got dict)\n[SQL: INSERT INTO user_sessions (user_id, session_token, refresh_token, device_info, ip_address, user_agent, is_active, is_revoked, expires_at, last_accessed, revoked_at, id, created_at, updated_at, deleted_at, is_deleted) VALUES ($1::UUID, $2::VARCHAR, $3::VARCHAR, $4::VARCHAR, $5::VARCHAR, $6::VARCHAR, $7::BOOLEAN, $8::BOOLEAN, $9::TIMESTAMP WITHOUT TIME ZONE, now(), $10::TIMESTAMP WITHOUT TIME ZONE, $11::UUID, now(), now(), $12::TIMESTAMP WITHOUT TIME ZONE, $13::BOOLEAN) RETURNING user_sessions.last_accessed, user_sessions.created_at, user_sessions.updated_at]\n[parameters: (UUID('0ca56c62-3f93-440c-95fa-e155bab28248'), None, 'eyJhbGciOiJIUzI1NiIsInR5cCI6IkpXVCJ9.eyJzdWIiOiIwY2E1NmM2Mi0zZjkzLTQ0MGMtOTVmYS1lMTU1YmFiMjgyNDgiLCJ0eXBlIjoicmVmcmVzaCIsImp0aSI6ImltdTFhczhmcjZSQWVZSWhZMGxmQ1U2ZWJsN3ZpVEVoMmhFSXBySkZKRmciLCJleHAiOjE3NTIzNjc2MDMsImlhdCI6MTc1MTc2MjgwM30.8WEf5vO44aHBK0xGSmFwXBWT5jiCioQ0VDjvajweq1o', {}, None, None, True, False, datetime.datetime(2025, 7, 13, 0, 46, 43, 347591), None, UUID('8b3c7277-4ab1-48a4-8eeb-94bbbf4be35e'), None, False)]\n(Background on this error at: https://sqlalche.me/e/20/dbapi)", "module": "auth", "function": "register_user", "line": 119, "thread": 281472873054240, "thread_name": "MainThread", "process": 10, "service": "adogent-backend", "environment": "development"}
{"timestamp": "2025-07-06T00:51:49.371943Z", "level": "ERROR", "logger": "adogent", "message": "Error logging test message", "module": "main", "function": "lifespan", "line": 34, "thread": 281473267896352, "thread_name": "MainThread", "process": 11, "service": "adogent-backend", "environment": "development"}
{"timestamp": "2025-07-06T00:51:49.372042Z", "level": "ERROR", "logger": "adogent", "message": "Error logging test message", "module": "main", "function": "lifespan", "line": 34, "thread": 281472856887328, "thread_name": "MainThread", "process": 13, "service": "adogent-backend", "environment": "development"}
{"timestamp": "2025-07-06T00:51:49.372096Z", "level": "ERROR", "logger": "adogent", "message": "Error logging test message", "module": "main", "function": "lifespan", "line": 34, "thread": 281473083158560, "thread_name": "MainThread", "process": 12, "service": "adogent-backend", "environment": "development"}
{"timestamp": "2025-07-06T00:51:49.374158Z", "level": "ERROR", "logger": "adogent", "message": "Error logging test message", "module": "main", "function": "lifespan", "line": 34, "thread": 281473008586784, "thread_name": "MainThread", "process": 10, "service": "adogent-backend", "environment": "development"}
{"timestamp": "2025-07-06T00:52:11.479177Z", "level": "ERROR", "logger": "adogent", "message": "Error: (sqlalchemy.dialects.postgresql.asyncpg.Error) <class 'asyncpg.exceptions.StringDataRightTruncationError'>: value too long for type character varying(255)\n[SQL: INSERT INTO user_sessions (user_id, session_token, refresh_token, device_info, ip_address, user_agent, is_active, is_revoked, expires_at, last_accessed, revoked_at, id, created_at, updated_at, deleted_at, is_deleted) VALUES ($1::UUID, $2::VARCHAR, $3::VARCHAR, $4::VARCHAR, $5::VARCHAR, $6::VARCHAR, $7::BOOLEAN, $8::BOOLEAN, $9::TIMESTAMP WITHOUT TIME ZONE, now(), $10::TIMESTAMP WITHOUT TIME ZONE, $11::UUID, now(), now(), $12::TIMESTAMP WITHOUT TIME ZONE, $13::BOOLEAN) RETURNING user_sessions.last_accessed, user_sessions.created_at, user_sessions.updated_at]\n[parameters: (UUID('b415a016-336e-4789-afbb-d630cf195592'), None, 'eyJhbGciOiJIUzI1NiIsInR5cCI6IkpXVCJ9.eyJzdWIiOiJiNDE1YTAxNi0zMzZlLTQ3ODktYWZiYi1kNjMwY2YxOTU1OTIiLCJ0eXBlIjoicmVmcmVzaCIsImp0aSI6IndnRzgwSWJBYjNUN2VnZkxlYlVXUzZxR1FpY1VEZUlNM0piWGhWYTVRMjgiLCJleHAiOjE3NTIzNjc5MzEsImlhdCI6MTc1MTc2MzEzMX0.ksVfIhMWXuYHThwEw8Bybd4otI00IhgXJtejmdM8CN0', None, None, None, True, False, datetime.datetime(2025, 7, 13, 0, 52, 11, 468174), None, UUID('17857f0a-33b1-4631-9c9c-9b9730fbf8d7'), None, False)]\n(Background on this error at: https://sqlalche.me/e/20/dbapi)", "module": "log", "function": "log_error", "line": 331, "thread": 281473008586784, "thread_name": "MainThread", "process": 10, "service": "adogent-backend", "environment": "development", "exception": {"type": "DBAPIError", "message": "(sqlalchemy.dialects.postgresql.asyncpg.Error) <class 'asyncpg.exceptions.StringDataRightTruncationError'>: value too long for type character varying(255)\n[SQL: INSERT INTO user_sessions (user_id, session_token, refresh_token, device_info, ip_address, user_agent, is_active, is_revoked, expires_at, last_accessed, revoked_at, id, created_at, updated_at, deleted_at, is_deleted) VALUES ($1::UUID, $2::VARCHAR, $3::VARCHAR, $4::VARCHAR, $5::VARCHAR, $6::VARCHAR, $7::BOOLEAN, $8::BOOLEAN, $9::TIMESTAMP WITHOUT TIME ZONE, now(), $10::TIMESTAMP WITHOUT TIME ZONE, $11::UUID, now(), now(), $12::TIMESTAMP WITHOUT TIME ZONE, $13::BOOLEAN) RETURNING user_sessions.last_accessed, user_sessions.created_at, user_sessions.updated_at]\n[parameters: (UUID('b415a016-336e-4789-afbb-d630cf195592'), None, 'eyJhbGciOiJIUzI1NiIsInR5cCI6IkpXVCJ9.eyJzdWIiOiJiNDE1YTAxNi0zMzZlLTQ3ODktYWZiYi1kNjMwY2YxOTU1OTIiLCJ0eXBlIjoicmVmcmVzaCIsImp0aSI6IndnRzgwSWJBYjNUN2VnZkxlYlVXUzZxR1FpY1VEZUlNM0piWGhWYTVRMjgiLCJleHAiOjE3NTIzNjc5MzEsImlhdCI6MTc1MTc2MzEzMX0.ksVfIhMWXuYHThwEw8Bybd4otI00IhgXJtejmdM8CN0', None, None, None, True, False, datetime.datetime(2025, 7, 13, 0, 52, 11, 468174), None, UUID('17857f0a-33b1-4631-9c9c-9b9730fbf8d7'), None, False)]\n(Background on this error at: https://sqlalche.me/e/20/dbapi)", "traceback": "Traceback (most recent call last):\n  File \"/usr/local/lib/python3.12/site-packages/sqlalchemy/dialects/postgresql/asyncpg.py\", line 534, in _prepare_and_execute\n    self._rows = deque(await prepared_stmt.fetch(*parameters))\n                       ^^^^^^^^^^^^^^^^^^^^^^^^^^^^^^^^^^^^^^\n  File \"/usr/local/lib/python3.12/site-packages/asyncpg/prepared_stmt.py\", line 176, in fetch\n    data = await self.__bind_execute(args, 0, timeout)\n           ^^^^^^^^^^^^^^^^^^^^^^^^^^^^^^^^^^^^^^^^^^^\n  File \"/usr/local/lib/python3.12/site-packages/asyncpg/prepared_stmt.py\", line 267, in __bind_execute\n    data, status, _ = await self.__do_execute(\n                      ^^^^^^^^^^^^^^^^^^^^^^^^\n  File \"/usr/local/lib/python3.12/site-packages/asyncpg/prepared_stmt.py\", line 256, in __do_execute\n    return await executor(protocol)\n           ^^^^^^^^^^^^^^^^^^^^^^^^\n  File \"asyncpg/protocol/protocol.pyx\", line 206, in bind_execute\nasyncpg.exceptions.StringDataRightTruncationError: value too long for type character varying(255)\n\nThe above exception was the direct cause of the following exception:\n\nTraceback (most recent call last):\n  File \"/usr/local/lib/python3.12/site-packages/sqlalchemy/engine/base.py\", line 1967, in _exec_single_context\n    self.dialect.do_execute(\n  File \"/usr/local/lib/python3.12/site-packages/sqlalchemy/engine/default.py\", line 941, in do_execute\n    cursor.execute(statement, parameters)\n  File \"/usr/local/lib/python3.12/site-packages/sqlalchemy/dialects/postgresql/asyncpg.py\", line 568, in execute\n    self._adapt_connection.await_(\n  File \"/usr/local/lib/python3.12/site-packages/sqlalchemy/util/_concurrency_py3k.py\", line 132, in await_only\n    return current.parent.switch(awaitable)  # type: ignore[no-any-return,attr-defined] # noqa: E501\n           ^^^^^^^^^^^^^^^^^^^^^^^^^^^^^^^^\n  File \"/usr/local/lib/python3.12/site-packages/sqlalchemy/util/_concurrency_py3k.py\", line 196, in greenlet_spawn\n    value = await result\n            ^^^^^^^^^^^^\n  File \"/usr/local/lib/python3.12/site-packages/sqlalchemy/dialects/postgresql/asyncpg.py\", line 546, in _prepare_and_execute\n    self._handle_exception(error)\n  File \"/usr/local/lib/python3.12/site-packages/sqlalchemy/dialects/postgresql/asyncpg.py\", line 497, in _handle_exception\n    self._adapt_connection._handle_exception(error)\n  File \"/usr/local/lib/python3.12/site-packages/sqlalchemy/dialects/postgresql/asyncpg.py\", line 780, in _handle_exception\n    raise translated_error from error\nsqlalchemy.dialects.postgresql.asyncpg.AsyncAdapt_asyncpg_dbapi.Error: <class 'asyncpg.exceptions.StringDataRightTruncationError'>: value too long for type character varying(255)\n\nThe above exception was the direct cause of the following exception:\n\nTraceback (most recent call last):\n  File \"/usr/app/app/services/auth_service.py\", line 122, in register_user\n    await self.db.commit()\n  File \"/usr/local/lib/python3.12/site-packages/sqlalchemy/ext/asyncio/session.py\", line 1009, in commit\n    await greenlet_spawn(self.sync_session.commit)\n  File \"/usr/local/lib/python3.12/site-packages/sqlalchemy/util/_concurrency_py3k.py\", line 203, in greenlet_spawn\n    result = context.switch(value)\n             ^^^^^^^^^^^^^^^^^^^^^\n  File \"/usr/local/lib/python3.12/site-packages/sqlalchemy/orm/session.py\", line 2028, in commit\n    trans.commit(_to_root=True)\n  File \"<string>\", line 2, in commit\n  File \"/usr/local/lib/python3.12/site-packages/sqlalchemy/orm/state_changes.py\", line 139, in _go\n    ret_value = fn(self, *arg, **kw)\n                ^^^^^^^^^^^^^^^^^^^^\n  File \"/usr/local/lib/python3.12/site-packages/sqlalchemy/orm/session.py\", line 1313, in commit\n    self._prepare_impl()\n  File \"<string>\", line 2, in _prepare_impl\n  File \"/usr/local/lib/python3.12/site-packages/sqlalchemy/orm/state_changes.py\", line 139, in _go\n    ret_value = fn(self, *arg, **kw)\n                ^^^^^^^^^^^^^^^^^^^^\n  File \"/usr/local/lib/python3.12/site-packages/sqlalchemy/orm/session.py\", line 1288, in _prepare_impl\n    self.session.flush()\n  File \"/usr/local/lib/python3.12/site-packages/sqlalchemy/orm/session.py\", line 4352, in flush\n    self._flush(objects)\n  File \"/usr/local/lib/python3.12/site-packages/sqlalchemy/orm/session.py\", line 4487, in _flush\n    with util.safe_reraise():\n         ^^^^^^^^^^^^^^^^^^^\n  File \"/usr/local/lib/python3.12/site-packages/sqlalchemy/util/langhelpers.py\", line 146, in __exit__\n    raise exc_value.with_traceback(exc_tb)\n  File \"/usr/local/lib/python3.12/site-packages/sqlalchemy/orm/session.py\", line 4448, in _flush\n    flush_context.execute()\n  File \"/usr/local/lib/python3.12/site-packages/sqlalchemy/orm/unitofwork.py\", line 466, in execute\n    rec.execute(self)\n  File \"/usr/local/lib/python3.12/site-packages/sqlalchemy/orm/unitofwork.py\", line 642, in execute\n    util.preloaded.orm_persistence.save_obj(\n  File \"/usr/local/lib/python3.12/site-packages/sqlalchemy/orm/persistence.py\", line 93, in save_obj\n    _emit_insert_statements(\n  File \"/usr/local/lib/python3.12/site-packages/sqlalchemy/orm/persistence.py\", line 1233, in _emit_insert_statements\n    result = connection.execute(\n             ^^^^^^^^^^^^^^^^^^^\n  File \"/usr/local/lib/python3.12/site-packages/sqlalchemy/engine/base.py\", line 1418, in execute\n    return meth(\n           ^^^^^\n  File \"/usr/local/lib/python3.12/site-packages/sqlalchemy/sql/elements.py\", line 515, in _execute_on_connection\n    return connection._execute_clauseelement(\n           ^^^^^^^^^^^^^^^^^^^^^^^^^^^^^^^^^^\n  File \"/usr/local/lib/python3.12/site-packages/sqlalchemy/engine/base.py\", line 1640, in _execute_clauseelement\n    ret = self._execute_context(\n          ^^^^^^^^^^^^^^^^^^^^^^\n  File \"/usr/local/lib/python3.12/site-packages/sqlalchemy/engine/base.py\", line 1846, in _execute_context\n    return self._exec_single_context(\n           ^^^^^^^^^^^^^^^^^^^^^^^^^^\n  File \"/usr/local/lib/python3.12/site-packages/sqlalchemy/engine/base.py\", line 1986, in _exec_single_context\n    self._handle_dbapi_exception(\n  File \"/usr/local/lib/python3.12/site-packages/sqlalchemy/engine/base.py\", line 2355, in _handle_dbapi_exception\n    raise sqlalchemy_exception.with_traceback(exc_info[2]) from e\n  File \"/usr/local/lib/python3.12/site-packages/sqlalchemy/engine/base.py\", line 1967, in _exec_single_context\n    self.dialect.do_execute(\n  File \"/usr/local/lib/python3.12/site-packages/sqlalchemy/engine/default.py\", line 941, in do_execute\n    cursor.execute(statement, parameters)\n  File \"/usr/local/lib/python3.12/site-packages/sqlalchemy/dialects/postgresql/asyncpg.py\", line 568, in execute\n    self._adapt_connection.await_(\n  File \"/usr/local/lib/python3.12/site-packages/sqlalchemy/util/_concurrency_py3k.py\", line 132, in await_only\n    return current.parent.switch(awaitable)  # type: ignore[no-any-return,attr-defined] # noqa: E501\n           ^^^^^^^^^^^^^^^^^^^^^^^^^^^^^^^^\n  File \"/usr/local/lib/python3.12/site-packages/sqlalchemy/util/_concurrency_py3k.py\", line 196, in greenlet_spawn\n    value = await result\n            ^^^^^^^^^^^^\n  File \"/usr/local/lib/python3.12/site-packages/sqlalchemy/dialects/postgresql/asyncpg.py\", line 546, in _prepare_and_execute\n    self._handle_exception(error)\n  File \"/usr/local/lib/python3.12/site-packages/sqlalchemy/dialects/postgresql/asyncpg.py\", line 497, in _handle_exception\n    self._adapt_connection._handle_exception(error)\n  File \"/usr/local/lib/python3.12/site-packages/sqlalchemy/dialects/postgresql/asyncpg.py\", line 780, in _handle_exception\n    raise translated_error from error\nsqlalchemy.exc.DBAPIError: (sqlalchemy.dialects.postgresql.asyncpg.Error) <class 'asyncpg.exceptions.StringDataRightTruncationError'>: value too long for type character varying(255)\n[SQL: INSERT INTO user_sessions (user_id, session_token, refresh_token, device_info, ip_address, user_agent, is_active, is_revoked, expires_at, last_accessed, revoked_at, id, created_at, updated_at, deleted_at, is_deleted) VALUES ($1::UUID, $2::VARCHAR, $3::VARCHAR, $4::VARCHAR, $5::VARCHAR, $6::VARCHAR, $7::BOOLEAN, $8::BOOLEAN, $9::TIMESTAMP WITHOUT TIME ZONE, now(), $10::TIMESTAMP WITHOUT TIME ZONE, $11::UUID, now(), now(), $12::TIMESTAMP WITHOUT TIME ZONE, $13::BOOLEAN) RETURNING user_sessions.last_accessed, user_sessions.created_at, user_sessions.updated_at]\n[parameters: (UUID('b415a016-336e-4789-afbb-d630cf195592'), None, 'eyJhbGciOiJIUzI1NiIsInR5cCI6IkpXVCJ9.eyJzdWIiOiJiNDE1YTAxNi0zMzZlLTQ3ODktYWZiYi1kNjMwY2YxOTU1OTIiLCJ0eXBlIjoicmVmcmVzaCIsImp0aSI6IndnRzgwSWJBYjNUN2VnZkxlYlVXUzZxR1FpY1VEZUlNM0piWGhWYTVRMjgiLCJleHAiOjE3NTIzNjc5MzEsImlhdCI6MTc1MTc2MzEzMX0.ksVfIhMWXuYHThwEw8Bybd4otI00IhgXJtejmdM8CN0', None, None, None, True, False, datetime.datetime(2025, 7, 13, 0, 52, 11, 468174), None, UUID('17857f0a-33b1-4631-9c9c-9b9730fbf8d7'), None, False)]\n(Background on this error at: https://sqlalche.me/e/20/dbapi)"}}
{"timestamp": "2025-07-06T00:52:11.480915Z", "level": "ERROR", "logger": "adogent", "message": "Registration error: (sqlalchemy.dialects.postgresql.asyncpg.Error) <class 'asyncpg.exceptions.StringDataRightTruncationError'>: value too long for type character varying(255)\n[SQL: INSERT INTO user_sessions (user_id, session_token, refresh_token, device_info, ip_address, user_agent, is_active, is_revoked, expires_at, last_accessed, revoked_at, id, created_at, updated_at, deleted_at, is_deleted) VALUES ($1::UUID, $2::VARCHAR, $3::VARCHAR, $4::VARCHAR, $5::VARCHAR, $6::VARCHAR, $7::BOOLEAN, $8::BOOLEAN, $9::TIMESTAMP WITHOUT TIME ZONE, now(), $10::TIMESTAMP WITHOUT TIME ZONE, $11::UUID, now(), now(), $12::TIMESTAMP WITHOUT TIME ZONE, $13::BOOLEAN) RETURNING user_sessions.last_accessed, user_sessions.created_at, user_sessions.updated_at]\n[parameters: (UUID('b415a016-336e-4789-afbb-d630cf195592'), None, 'eyJhbGciOiJIUzI1NiIsInR5cCI6IkpXVCJ9.eyJzdWIiOiJiNDE1YTAxNi0zMzZlLTQ3ODktYWZiYi1kNjMwY2YxOTU1OTIiLCJ0eXBlIjoicmVmcmVzaCIsImp0aSI6IndnRzgwSWJBYjNUN2VnZkxlYlVXUzZxR1FpY1VEZUlNM0piWGhWYTVRMjgiLCJleHAiOjE3NTIzNjc5MzEsImlhdCI6MTc1MTc2MzEzMX0.ksVfIhMWXuYHThwEw8Bybd4otI00IhgXJtejmdM8CN0', None, None, None, True, False, datetime.datetime(2025, 7, 13, 0, 52, 11, 468174), None, UUID('17857f0a-33b1-4631-9c9c-9b9730fbf8d7'), None, False)]\n(Background on this error at: https://sqlalche.me/e/20/dbapi)", "module": "auth", "function": "register_user", "line": 119, "thread": 281473008586784, "thread_name": "MainThread", "process": 10, "service": "adogent-backend", "environment": "development"}
{"timestamp": "2025-07-06T01:00:50.799405Z", "level": "ERROR", "logger": "adogent", "message": "Error logging test message", "module": "main", "function": "lifespan", "line": 34, "thread": 281473732759584, "thread_name": "MainThread", "process": 12, "service": "adogent-backend", "environment": "development"}
{"timestamp": "2025-07-06T01:00:50.799591Z", "level": "ERROR", "logger": "adogent", "message": "Error logging test message", "module": "main", "function": "lifespan", "line": 34, "thread": 281472862773280, "thread_name": "MainThread", "process": 11, "service": "adogent-backend", "environment": "development"}
{"timestamp": "2025-07-06T01:00:50.799624Z", "level": "ERROR", "logger": "adogent", "message": "Error logging test message", "module": "main", "function": "lifespan", "line": 34, "thread": 281473395978272, "thread_name": "MainThread", "process": 13, "service": "adogent-backend", "environment": "development"}
{"timestamp": "2025-07-06T01:00:50.800544Z", "level": "ERROR", "logger": "adogent", "message": "Error logging test message", "module": "main", "function": "lifespan", "line": 34, "thread": 281473163030560, "thread_name": "MainThread", "process": 10, "service": "adogent-backend", "environment": "development"}
{"timestamp": "2025-07-06T01:00:58.785557Z", "level": "ERROR", "logger": "adogent", "message": "Error: (sqlalchemy.dialects.postgresql.asyncpg.IntegrityError) <class 'asyncpg.exceptions.NotNullViolationError'>: null value in column \"session_token\" of relation \"user_sessions\" violates not-null constraint\nDETAIL:  Failing row contains (f5ffa9aa-fd4d-4197-bcaa-fd9e1c0a622b, null, eyJhbGciOiJIUzI1NiIsInR5cCI6IkpXVCJ9.eyJ1IjoiZjVmZmE5YWEtZmQ0ZC0..., null, null, null, t, f, 2025-07-13 01:00:58.777706, 2025-07-06 01:00:58.52137, null, afeef463-688a-458b-aab5-f7475aac1657, 2025-07-06 01:00:58.52137, 2025-07-06 01:00:58.52137, null, f).\n[SQL: INSERT INTO user_sessions (user_id, session_token, refresh_token, device_info, ip_address, user_agent, is_active, is_revoked, expires_at, last_accessed, revoked_at, id, created_at, updated_at, deleted_at, is_deleted) VALUES ($1::UUID, $2::VARCHAR, $3::VARCHAR, $4::VARCHAR, $5::VARCHAR, $6::VARCHAR, $7::BOOLEAN, $8::BOOLEAN, $9::TIMESTAMP WITHOUT TIME ZONE, now(), $10::TIMESTAMP WITHOUT TIME ZONE, $11::UUID, now(), now(), $12::TIMESTAMP WITHOUT TIME ZONE, $13::BOOLEAN) RETURNING user_sessions.last_accessed, user_sessions.created_at, user_sessions.updated_at]\n[parameters: (UUID('f5ffa9aa-fd4d-4197-bcaa-fd9e1c0a622b'), None, 'eyJhbGciOiJIUzI1NiIsInR5cCI6IkpXVCJ9.eyJ1IjoiZjVmZmE5YWEtZmQ0ZC00MTk3LWJjYWEtZmQ5ZTFjMGE2MjJiIiwidCI6InIiLCJpIjoiRlBaV1drSUZHUHRFaHI1TzFYNFZIUSIsImV4cCI6MTc1MjM2ODQ1OH0.zUHWtqCuq1BNYenzITrNZ7iz1DUByS_FsMW4eWEJc7g', None, None, None, True, False, datetime.datetime(2025, 7, 13, 1, 0, 58, 777706), None, UUID('afeef463-688a-458b-aab5-f7475aac1657'), None, False)]\n(Background on this error at: https://sqlalche.me/e/20/gkpj)", "module": "log", "function": "log_error", "line": 331, "thread": 281473732759584, "thread_name": "MainThread", "process": 12, "service": "adogent-backend", "environment": "development", "exception": {"type": "IntegrityError", "message": "(sqlalchemy.dialects.postgresql.asyncpg.IntegrityError) <class 'asyncpg.exceptions.NotNullViolationError'>: null value in column \"session_token\" of relation \"user_sessions\" violates not-null constraint\nDETAIL:  Failing row contains (f5ffa9aa-fd4d-4197-bcaa-fd9e1c0a622b, null, eyJhbGciOiJIUzI1NiIsInR5cCI6IkpXVCJ9.eyJ1IjoiZjVmZmE5YWEtZmQ0ZC0..., null, null, null, t, f, 2025-07-13 01:00:58.777706, 2025-07-06 01:00:58.52137, null, afeef463-688a-458b-aab5-f7475aac1657, 2025-07-06 01:00:58.52137, 2025-07-06 01:00:58.52137, null, f).\n[SQL: INSERT INTO user_sessions (user_id, session_token, refresh_token, device_info, ip_address, user_agent, is_active, is_revoked, expires_at, last_accessed, revoked_at, id, created_at, updated_at, deleted_at, is_deleted) VALUES ($1::UUID, $2::VARCHAR, $3::VARCHAR, $4::VARCHAR, $5::VARCHAR, $6::VARCHAR, $7::BOOLEAN, $8::BOOLEAN, $9::TIMESTAMP WITHOUT TIME ZONE, now(), $10::TIMESTAMP WITHOUT TIME ZONE, $11::UUID, now(), now(), $12::TIMESTAMP WITHOUT TIME ZONE, $13::BOOLEAN) RETURNING user_sessions.last_accessed, user_sessions.created_at, user_sessions.updated_at]\n[parameters: (UUID('f5ffa9aa-fd4d-4197-bcaa-fd9e1c0a622b'), None, 'eyJhbGciOiJIUzI1NiIsInR5cCI6IkpXVCJ9.eyJ1IjoiZjVmZmE5YWEtZmQ0ZC00MTk3LWJjYWEtZmQ5ZTFjMGE2MjJiIiwidCI6InIiLCJpIjoiRlBaV1drSUZHUHRFaHI1TzFYNFZIUSIsImV4cCI6MTc1MjM2ODQ1OH0.zUHWtqCuq1BNYenzITrNZ7iz1DUByS_FsMW4eWEJc7g', None, None, None, True, False, datetime.datetime(2025, 7, 13, 1, 0, 58, 777706), None, UUID('afeef463-688a-458b-aab5-f7475aac1657'), None, False)]\n(Background on this error at: https://sqlalche.me/e/20/gkpj)", "traceback": "Traceback (most recent call last):\n  File \"/usr/local/lib/python3.12/site-packages/sqlalchemy/dialects/postgresql/asyncpg.py\", line 534, in _prepare_and_execute\n    self._rows = deque(await prepared_stmt.fetch(*parameters))\n                       ^^^^^^^^^^^^^^^^^^^^^^^^^^^^^^^^^^^^^^\n  File \"/usr/local/lib/python3.12/site-packages/asyncpg/prepared_stmt.py\", line 176, in fetch\n    data = await self.__bind_execute(args, 0, timeout)\n           ^^^^^^^^^^^^^^^^^^^^^^^^^^^^^^^^^^^^^^^^^^^\n  File \"/usr/local/lib/python3.12/site-packages/asyncpg/prepared_stmt.py\", line 267, in __bind_execute\n    data, status, _ = await self.__do_execute(\n                      ^^^^^^^^^^^^^^^^^^^^^^^^\n  File \"/usr/local/lib/python3.12/site-packages/asyncpg/prepared_stmt.py\", line 256, in __do_execute\n    return await executor(protocol)\n           ^^^^^^^^^^^^^^^^^^^^^^^^\n  File \"asyncpg/protocol/protocol.pyx\", line 206, in bind_execute\nasyncpg.exceptions.NotNullViolationError: null value in column \"session_token\" of relation \"user_sessions\" violates not-null constraint\nDETAIL:  Failing row contains (f5ffa9aa-fd4d-4197-bcaa-fd9e1c0a622b, null, eyJhbGciOiJIUzI1NiIsInR5cCI6IkpXVCJ9.eyJ1IjoiZjVmZmE5YWEtZmQ0ZC0..., null, null, null, t, f, 2025-07-13 01:00:58.777706, 2025-07-06 01:00:58.52137, null, afeef463-688a-458b-aab5-f7475aac1657, 2025-07-06 01:00:58.52137, 2025-07-06 01:00:58.52137, null, f).\n\nThe above exception was the direct cause of the following exception:\n\nTraceback (most recent call last):\n  File \"/usr/local/lib/python3.12/site-packages/sqlalchemy/engine/base.py\", line 1967, in _exec_single_context\n    self.dialect.do_execute(\n  File \"/usr/local/lib/python3.12/site-packages/sqlalchemy/engine/default.py\", line 941, in do_execute\n    cursor.execute(statement, parameters)\n  File \"/usr/local/lib/python3.12/site-packages/sqlalchemy/dialects/postgresql/asyncpg.py\", line 568, in execute\n    self._adapt_connection.await_(\n  File \"/usr/local/lib/python3.12/site-packages/sqlalchemy/util/_concurrency_py3k.py\", line 132, in await_only\n    return current.parent.switch(awaitable)  # type: ignore[no-any-return,attr-defined] # noqa: E501\n           ^^^^^^^^^^^^^^^^^^^^^^^^^^^^^^^^\n  File \"/usr/local/lib/python3.12/site-packages/sqlalchemy/util/_concurrency_py3k.py\", line 196, in greenlet_spawn\n    value = await result\n            ^^^^^^^^^^^^\n  File \"/usr/local/lib/python3.12/site-packages/sqlalchemy/dialects/postgresql/asyncpg.py\", line 546, in _prepare_and_execute\n    self._handle_exception(error)\n  File \"/usr/local/lib/python3.12/site-packages/sqlalchemy/dialects/postgresql/asyncpg.py\", line 497, in _handle_exception\n    self._adapt_connection._handle_exception(error)\n  File \"/usr/local/lib/python3.12/site-packages/sqlalchemy/dialects/postgresql/asyncpg.py\", line 780, in _handle_exception\n    raise translated_error from error\nsqlalchemy.dialects.postgresql.asyncpg.AsyncAdapt_asyncpg_dbapi.IntegrityError: <class 'asyncpg.exceptions.NotNullViolationError'>: null value in column \"session_token\" of relation \"user_sessions\" violates not-null constraint\nDETAIL:  Failing row contains (f5ffa9aa-fd4d-4197-bcaa-fd9e1c0a622b, null, eyJhbGciOiJIUzI1NiIsInR5cCI6IkpXVCJ9.eyJ1IjoiZjVmZmE5YWEtZmQ0ZC0..., null, null, null, t, f, 2025-07-13 01:00:58.777706, 2025-07-06 01:00:58.52137, null, afeef463-688a-458b-aab5-f7475aac1657, 2025-07-06 01:00:58.52137, 2025-07-06 01:00:58.52137, null, f).\n\nThe above exception was the direct cause of the following exception:\n\nTraceback (most recent call last):\n  File \"/usr/app/app/services/auth_service.py\", line 122, in register_user\n    await self.db.commit()\n  File \"/usr/local/lib/python3.12/site-packages/sqlalchemy/ext/asyncio/session.py\", line 1009, in commit\n    await greenlet_spawn(self.sync_session.commit)\n  File \"/usr/local/lib/python3.12/site-packages/sqlalchemy/util/_concurrency_py3k.py\", line 203, in greenlet_spawn\n    result = context.switch(value)\n             ^^^^^^^^^^^^^^^^^^^^^\n  File \"/usr/local/lib/python3.12/site-packages/sqlalchemy/orm/session.py\", line 2028, in commit\n    trans.commit(_to_root=True)\n  File \"<string>\", line 2, in commit\n  File \"/usr/local/lib/python3.12/site-packages/sqlalchemy/orm/state_changes.py\", line 139, in _go\n    ret_value = fn(self, *arg, **kw)\n                ^^^^^^^^^^^^^^^^^^^^\n  File \"/usr/local/lib/python3.12/site-packages/sqlalchemy/orm/session.py\", line 1313, in commit\n    self._prepare_impl()\n  File \"<string>\", line 2, in _prepare_impl\n  File \"/usr/local/lib/python3.12/site-packages/sqlalchemy/orm/state_changes.py\", line 139, in _go\n    ret_value = fn(self, *arg, **kw)\n                ^^^^^^^^^^^^^^^^^^^^\n  File \"/usr/local/lib/python3.12/site-packages/sqlalchemy/orm/session.py\", line 1288, in _prepare_impl\n    self.session.flush()\n  File \"/usr/local/lib/python3.12/site-packages/sqlalchemy/orm/session.py\", line 4352, in flush\n    self._flush(objects)\n  File \"/usr/local/lib/python3.12/site-packages/sqlalchemy/orm/session.py\", line 4487, in _flush\n    with util.safe_reraise():\n         ^^^^^^^^^^^^^^^^^^^\n  File \"/usr/local/lib/python3.12/site-packages/sqlalchemy/util/langhelpers.py\", line 146, in __exit__\n    raise exc_value.with_traceback(exc_tb)\n  File \"/usr/local/lib/python3.12/site-packages/sqlalchemy/orm/session.py\", line 4448, in _flush\n    flush_context.execute()\n  File \"/usr/local/lib/python3.12/site-packages/sqlalchemy/orm/unitofwork.py\", line 466, in execute\n    rec.execute(self)\n  File \"/usr/local/lib/python3.12/site-packages/sqlalchemy/orm/unitofwork.py\", line 642, in execute\n    util.preloaded.orm_persistence.save_obj(\n  File \"/usr/local/lib/python3.12/site-packages/sqlalchemy/orm/persistence.py\", line 93, in save_obj\n    _emit_insert_statements(\n  File \"/usr/local/lib/python3.12/site-packages/sqlalchemy/orm/persistence.py\", line 1233, in _emit_insert_statements\n    result = connection.execute(\n             ^^^^^^^^^^^^^^^^^^^\n  File \"/usr/local/lib/python3.12/site-packages/sqlalchemy/engine/base.py\", line 1418, in execute\n    return meth(\n           ^^^^^\n  File \"/usr/local/lib/python3.12/site-packages/sqlalchemy/sql/elements.py\", line 515, in _execute_on_connection\n    return connection._execute_clauseelement(\n           ^^^^^^^^^^^^^^^^^^^^^^^^^^^^^^^^^^\n  File \"/usr/local/lib/python3.12/site-packages/sqlalchemy/engine/base.py\", line 1640, in _execute_clauseelement\n    ret = self._execute_context(\n          ^^^^^^^^^^^^^^^^^^^^^^\n  File \"/usr/local/lib/python3.12/site-packages/sqlalchemy/engine/base.py\", line 1846, in _execute_context\n    return self._exec_single_context(\n           ^^^^^^^^^^^^^^^^^^^^^^^^^^\n  File \"/usr/local/lib/python3.12/site-packages/sqlalchemy/engine/base.py\", line 1986, in _exec_single_context\n    self._handle_dbapi_exception(\n  File \"/usr/local/lib/python3.12/site-packages/sqlalchemy/engine/base.py\", line 2355, in _handle_dbapi_exception\n    raise sqlalchemy_exception.with_traceback(exc_info[2]) from e\n  File \"/usr/local/lib/python3.12/site-packages/sqlalchemy/engine/base.py\", line 1967, in _exec_single_context\n    self.dialect.do_execute(\n  File \"/usr/local/lib/python3.12/site-packages/sqlalchemy/engine/default.py\", line 941, in do_execute\n    cursor.execute(statement, parameters)\n  File \"/usr/local/lib/python3.12/site-packages/sqlalchemy/dialects/postgresql/asyncpg.py\", line 568, in execute\n    self._adapt_connection.await_(\n  File \"/usr/local/lib/python3.12/site-packages/sqlalchemy/util/_concurrency_py3k.py\", line 132, in await_only\n    return current.parent.switch(awaitable)  # type: ignore[no-any-return,attr-defined] # noqa: E501\n           ^^^^^^^^^^^^^^^^^^^^^^^^^^^^^^^^\n  File \"/usr/local/lib/python3.12/site-packages/sqlalchemy/util/_concurrency_py3k.py\", line 196, in greenlet_spawn\n    value = await result\n            ^^^^^^^^^^^^\n  File \"/usr/local/lib/python3.12/site-packages/sqlalchemy/dialects/postgresql/asyncpg.py\", line 546, in _prepare_and_execute\n    self._handle_exception(error)\n  File \"/usr/local/lib/python3.12/site-packages/sqlalchemy/dialects/postgresql/asyncpg.py\", line 497, in _handle_exception\n    self._adapt_connection._handle_exception(error)\n  File \"/usr/local/lib/python3.12/site-packages/sqlalchemy/dialects/postgresql/asyncpg.py\", line 780, in _handle_exception\n    raise translated_error from error\nsqlalchemy.exc.IntegrityError: (sqlalchemy.dialects.postgresql.asyncpg.IntegrityError) <class 'asyncpg.exceptions.NotNullViolationError'>: null value in column \"session_token\" of relation \"user_sessions\" violates not-null constraint\nDETAIL:  Failing row contains (f5ffa9aa-fd4d-4197-bcaa-fd9e1c0a622b, null, eyJhbGciOiJIUzI1NiIsInR5cCI6IkpXVCJ9.eyJ1IjoiZjVmZmE5YWEtZmQ0ZC0..., null, null, null, t, f, 2025-07-13 01:00:58.777706, 2025-07-06 01:00:58.52137, null, afeef463-688a-458b-aab5-f7475aac1657, 2025-07-06 01:00:58.52137, 2025-07-06 01:00:58.52137, null, f).\n[SQL: INSERT INTO user_sessions (user_id, session_token, refresh_token, device_info, ip_address, user_agent, is_active, is_revoked, expires_at, last_accessed, revoked_at, id, created_at, updated_at, deleted_at, is_deleted) VALUES ($1::UUID, $2::VARCHAR, $3::VARCHAR, $4::VARCHAR, $5::VARCHAR, $6::VARCHAR, $7::BOOLEAN, $8::BOOLEAN, $9::TIMESTAMP WITHOUT TIME ZONE, now(), $10::TIMESTAMP WITHOUT TIME ZONE, $11::UUID, now(), now(), $12::TIMESTAMP WITHOUT TIME ZONE, $13::BOOLEAN) RETURNING user_sessions.last_accessed, user_sessions.created_at, user_sessions.updated_at]\n[parameters: (UUID('f5ffa9aa-fd4d-4197-bcaa-fd9e1c0a622b'), None, 'eyJhbGciOiJIUzI1NiIsInR5cCI6IkpXVCJ9.eyJ1IjoiZjVmZmE5YWEtZmQ0ZC00MTk3LWJjYWEtZmQ5ZTFjMGE2MjJiIiwidCI6InIiLCJpIjoiRlBaV1drSUZHUHRFaHI1TzFYNFZIUSIsImV4cCI6MTc1MjM2ODQ1OH0.zUHWtqCuq1BNYenzITrNZ7iz1DUByS_FsMW4eWEJc7g', None, None, None, True, False, datetime.datetime(2025, 7, 13, 1, 0, 58, 777706), None, UUID('afeef463-688a-458b-aab5-f7475aac1657'), None, False)]\n(Background on this error at: https://sqlalche.me/e/20/gkpj)"}}
{"timestamp": "2025-07-06T01:00:58.787693Z", "level": "ERROR", "logger": "adogent", "message": "Registration error: (sqlalchemy.dialects.postgresql.asyncpg.IntegrityError) <class 'asyncpg.exceptions.NotNullViolationError'>: null value in column \"session_token\" of relation \"user_sessions\" violates not-null constraint\nDETAIL:  Failing row contains (f5ffa9aa-fd4d-4197-bcaa-fd9e1c0a622b, null, eyJhbGciOiJIUzI1NiIsInR5cCI6IkpXVCJ9.eyJ1IjoiZjVmZmE5YWEtZmQ0ZC0..., null, null, null, t, f, 2025-07-13 01:00:58.777706, 2025-07-06 01:00:58.52137, null, afeef463-688a-458b-aab5-f7475aac1657, 2025-07-06 01:00:58.52137, 2025-07-06 01:00:58.52137, null, f).\n[SQL: INSERT INTO user_sessions (user_id, session_token, refresh_token, device_info, ip_address, user_agent, is_active, is_revoked, expires_at, last_accessed, revoked_at, id, created_at, updated_at, deleted_at, is_deleted) VALUES ($1::UUID, $2::VARCHAR, $3::VARCHAR, $4::VARCHAR, $5::VARCHAR, $6::VARCHAR, $7::BOOLEAN, $8::BOOLEAN, $9::TIMESTAMP WITHOUT TIME ZONE, now(), $10::TIMESTAMP WITHOUT TIME ZONE, $11::UUID, now(), now(), $12::TIMESTAMP WITHOUT TIME ZONE, $13::BOOLEAN) RETURNING user_sessions.last_accessed, user_sessions.created_at, user_sessions.updated_at]\n[parameters: (UUID('f5ffa9aa-fd4d-4197-bcaa-fd9e1c0a622b'), None, 'eyJhbGciOiJIUzI1NiIsInR5cCI6IkpXVCJ9.eyJ1IjoiZjVmZmE5YWEtZmQ0ZC00MTk3LWJjYWEtZmQ5ZTFjMGE2MjJiIiwidCI6InIiLCJpIjoiRlBaV1drSUZHUHRFaHI1TzFYNFZIUSIsImV4cCI6MTc1MjM2ODQ1OH0.zUHWtqCuq1BNYenzITrNZ7iz1DUByS_FsMW4eWEJc7g', None, None, None, True, False, datetime.datetime(2025, 7, 13, 1, 0, 58, 777706), None, UUID('afeef463-688a-458b-aab5-f7475aac1657'), None, False)]\n(Background on this error at: https://sqlalche.me/e/20/gkpj)", "module": "auth", "function": "register_user", "line": 119, "thread": 281473732759584, "thread_name": "MainThread", "process": 12, "service": "adogent-backend", "environment": "development"}
{"timestamp": "2025-07-06T01:08:28.741365Z", "level": "ERROR", "logger": "adogent", "message": "Error logging test message", "module": "main", "function": "lifespan", "line": 34, "thread": 281473105002528, "thread_name": "MainThread", "process": 10, "service": "adogent-backend", "environment": "development"}
{"timestamp": "2025-07-06T01:08:28.741406Z", "level": "ERROR", "logger": "adogent", "message": "Error logging test message", "module": "main", "function": "lifespan", "line": 34, "thread": 281473128271904, "thread_name": "MainThread", "process": 13, "service": "adogent-backend", "environment": "development"}
{"timestamp": "2025-07-06T01:08:28.741416Z", "level": "ERROR", "logger": "adogent", "message": "Error logging test message", "module": "main", "function": "lifespan", "line": 34, "thread": 281473123180576, "thread_name": "MainThread", "process": 12, "service": "adogent-backend", "environment": "development"}
{"timestamp": "2025-07-06T01:08:28.742325Z", "level": "ERROR", "logger": "adogent", "message": "Error logging test message", "module": "main", "function": "lifespan", "line": 34, "thread": 281473052758048, "thread_name": "MainThread", "process": 11, "service": "adogent-backend", "environment": "development"}
{"timestamp": "2025-07-06T01:09:58.322223Z", "level": "ERROR", "logger": "adogent", "message": "Error: 'User' object has no attribute 'login_count'", "module": "log", "function": "log_error", "line": 331, "thread": 281473105002528, "thread_name": "MainThread", "process": 10, "service": "adogent-backend", "environment": "development", "exception": {"type": "AttributeError", "message": "'User' object has no attribute 'login_count'", "traceback": "Traceback (most recent call last):\n  File \"/usr/app/app/services/auth_service.py\", line 190, in authenticate_user\n    user.login_count = (user.login_count or 0) + 1\n                        ^^^^^^^^^^^^^^^^\nAttributeError: 'User' object has no attribute 'login_count'"}}
{"timestamp": "2025-07-06T01:09:58.323306Z", "level": "ERROR", "logger": "adogent", "message": "Login error: 'User' object has no attribute 'login_count'", "module": "auth", "function": "login_user", "line": 171, "thread": 281473105002528, "thread_name": "MainThread", "process": 10, "service": "adogent-backend", "environment": "development"}
{"timestamp": "2025-07-06T01:12:39.560251Z", "level": "ERROR", "logger": "adogent", "message": "Error logging test message", "module": "main", "function": "lifespan", "line": 34, "thread": 281473066512416, "thread_name": "MainThread", "process": 12, "service": "adogent-backend", "environment": "development"}
{"timestamp": "2025-07-06T01:12:39.560329Z", "level": "ERROR", "logger": "adogent", "message": "Error logging test message", "module": "main", "function": "lifespan", "line": 34, "thread": 281473317838880, "thread_name": "MainThread", "process": 11, "service": "adogent-backend", "environment": "development"}
{"timestamp": "2025-07-06T01:12:39.561946Z", "level": "ERROR", "logger": "adogent", "message": "Error logging test message", "module": "main", "function": "lifespan", "line": 34, "thread": 281473811079200, "thread_name": "MainThread", "process": 13, "service": "adogent-backend", "environment": "development"}
{"timestamp": "2025-07-06T01:12:39.562071Z", "level": "ERROR", "logger": "adogent", "message": "Error logging test message", "module": "main", "function": "lifespan", "line": 34, "thread": 281473207636000, "thread_name": "MainThread", "process": 10, "service": "adogent-backend", "environment": "development"}
{"timestamp": "2025-07-06T01:13:48.519523Z", "level": "ERROR", "logger": "adogent", "message": "Get profile error: 2 validation errors for UserResponse\nai_interaction_style\n  Field required [type=missing, input_value={'id': UUID('5832571c-407..., 6, 1, 12, 48, 133995)}, input_type=dict]\n    For further information visit https://errors.pydantic.dev/2.11/v/missing\nupdated_at\n  Field required [type=missing, input_value={'id': UUID('5832571c-407..., 6, 1, 12, 48, 133995)}, input_type=dict]\n    For further information visit https://errors.pydantic.dev/2.11/v/missing", "module": "auth", "function": "get_current_user_profile", "line": 278, "thread": 281473811079200, "thread_name": "MainThread", "process": 13, "service": "adogent-backend", "environment": "development"}
{"timestamp": "2025-07-06T01:22:38.619718Z", "level": "ERROR", "logger": "adogent", "message": "Error logging test message", "module": "main", "function": "lifespan", "line": 34, "thread": 281472879845408, "thread_name": "MainThread", "process": 12, "service": "adogent-backend", "environment": "development"}
{"timestamp": "2025-07-06T01:22:38.621156Z", "level": "ERROR", "logger": "adogent", "message": "Error logging test message", "module": "main", "function": "lifespan", "line": 34, "thread": 281473729888288, "thread_name": "MainThread", "process": 13, "service": "adogent-backend", "environment": "development"}
{"timestamp": "2025-07-06T01:22:38.622602Z", "level": "ERROR", "logger": "adogent", "message": "Error logging test message", "module": "main", "function": "lifespan", "line": 34, "thread": 281473649844256, "thread_name": "MainThread", "process": 10, "service": "adogent-backend", "environment": "development"}
{"timestamp": "2025-07-06T01:22:38.627140Z", "level": "ERROR", "logger": "adogent", "message": "Error logging test message", "module": "main", "function": "lifespan", "line": 34, "thread": 281473295638560, "thread_name": "MainThread", "process": 11, "service": "adogent-backend", "environment": "development"}
{"timestamp": "2025-07-06T11:52:38.156160Z", "level": "ERROR", "logger": "adogent", "message": "Error logging test message", "module": "main", "function": "lifespan", "line": 34, "thread": 281472971288608, "thread_name": "MainThread", "process": 13, "service": "adogent-backend", "environment": "development"}
{"timestamp": "2025-07-06T11:52:38.156664Z", "level": "ERROR", "logger": "adogent", "message": "Error logging test message", "module": "main", "function": "lifespan", "line": 34, "thread": 281473839595552, "thread_name": "MainThread", "process": 14, "service": "adogent-backend", "environment": "development"}
{"timestamp": "2025-07-06T11:52:38.157541Z", "level": "ERROR", "logger": "adogent", "message": "Error logging test message", "module": "main", "function": "lifespan", "line": 34, "thread": 281472959635488, "thread_name": "MainThread", "process": 11, "service": "adogent-backend", "environment": "development"}
{"timestamp": "2025-07-06T11:52:38.158153Z", "level": "ERROR", "logger": "adogent", "message": "Error logging test message", "module": "main", "function": "lifespan", "line": 34, "thread": 281473287266336, "thread_name": "MainThread", "process": 12, "service": "adogent-backend", "environment": "development"}
{"timestamp": "2025-07-06T11:53:08.823463Z", "level": "ERROR", "logger": "adogent", "message": "Error logging test message", "module": "main", "function": "lifespan", "line": 34, "thread": 281473405861920, "thread_name": "MainThread", "process": 10, "service": "adogent-backend", "environment": "development"}
{"timestamp": "2025-07-06T11:53:08.842217Z", "level": "ERROR", "logger": "adogent", "message": "Error logging test message", "module": "main", "function": "lifespan", "line": 34, "thread": 281473853448224, "thread_name": "MainThread", "process": 11, "service": "adogent-backend", "environment": "development"}
{"timestamp": "2025-07-06T11:53:08.842566Z", "level": "ERROR", "logger": "adogent", "message": "Error logging test message", "module": "main", "function": "lifespan", "line": 34, "thread": 281473174790176, "thread_name": "MainThread", "process": 12, "service": "adogent-backend", "environment": "development"}
{"timestamp": "2025-07-06T11:53:08.842907Z", "level": "ERROR", "logger": "adogent", "message": "Error logging test message", "module": "main", "function": "lifespan", "line": 34, "thread": 281473710342176, "thread_name": "MainThread", "process": 13, "service": "adogent-backend", "environment": "development"}
{"timestamp": "2025-07-06T11:56:30.154593Z", "level": "ERROR", "logger": "adogent", "message": "Error: 'UserCreateRequest' object has no attribute 'date_of_birth'", "module": "log", "function": "log_error", "line": 331, "thread": 281473405861920, "thread_name": "MainThread", "process": 10, "service": "adogent-backend", "environment": "development", "exception": {"type": "AttributeError", "message": "'UserCreateRequest' object has no attribute 'date_of_birth'", "traceback": "Traceback (most recent call last):\n  File \"/usr/app/app/services/auth_service.py\", line 68, in register_user\n    new_user = await self.user_service.create_user(user_data)\n               ^^^^^^^^^^^^^^^^^^^^^^^^^^^^^^^^^^^^^^^^^^^^^^\n  File \"/usr/app/app/services/user_service.py\", line 72, in create_user\n    date_of_birth=user_data.date_of_birth,\n                  ^^^^^^^^^^^^^^^^^^^^^^^\n  File \"/usr/local/lib/python3.12/site-packages/pydantic/main.py\", line 984, in __getattr__\n    raise AttributeError(f'{type(self).__name__!r} object has no attribute {item!r}')\nAttributeError: 'UserCreateRequest' object has no attribute 'date_of_birth'"}}
{"timestamp": "2025-07-06T11:56:30.156443Z", "level": "ERROR", "logger": "adogent", "message": "Registration error: 'UserCreateRequest' object has no attribute 'date_of_birth'", "module": "auth", "function": "register_user", "line": 78, "thread": 281473405861920, "thread_name": "MainThread", "process": 10, "service": "adogent-backend", "environment": "development"}
{"timestamp": "2025-07-06T12:02:43.862334Z", "level": "ERROR", "logger": "adogent", "message": "Error logging test message", "module": "main", "function": "lifespan", "line": 34, "thread": 281472906883104, "thread_name": "MainThread", "process": 10, "service": "adogent-backend", "environment": "development"}
{"timestamp": "2025-07-06T12:02:43.862717Z", "level": "ERROR", "logger": "adogent", "message": "Error logging test message", "module": "main", "function": "lifespan", "line": 34, "thread": 281473365585952, "thread_name": "MainThread", "process": 13, "service": "adogent-backend", "environment": "development"}
{"timestamp": "2025-07-06T12:02:43.863210Z", "level": "ERROR", "logger": "adogent", "message": "Error logging test message", "module": "main", "function": "lifespan", "line": 34, "thread": 281473087528992, "thread_name": "MainThread", "process": 11, "service": "adogent-backend", "environment": "development"}
{"timestamp": "2025-07-06T12:02:43.867223Z", "level": "ERROR", "logger": "adogent", "message": "Error logging test message", "module": "main", "function": "lifespan", "line": 34, "thread": 281473843421216, "thread_name": "MainThread", "process": 12, "service": "adogent-backend", "environment": "development"}
{"timestamp": "2025-07-06T12:02:54.591454Z", "level": "ERROR", "logger": "adogent", "message": "Registration error: 2 validation errors for AuthTokenResponse\nuser.ai_interaction_style\n  Field required [type=missing, input_value=UserResponse(email='jane....06900), last_login=None), input_type=UserResponse]\n    For further information visit https://errors.pydantic.dev/2.11/v/missing\nuser.updated_at\n  Field required [type=missing, input_value=UserResponse(email='jane....06900), last_login=None), input_type=UserResponse]\n    For further information visit https://errors.pydantic.dev/2.11/v/missing", "module": "auth", "function": "register_user", "line": 78, "thread": 281472906883104, "thread_name": "MainThread", "process": 10, "service": "adogent-backend", "environment": "development"}
{"timestamp": "2025-07-06T12:08:49.647818Z", "level": "ERROR", "logger": "adogent", "message": "Error logging test message", "module": "main", "function": "lifespan", "line": 34, "thread": 281473364774944, "thread_name": "MainThread", "process": 13, "service": "adogent-backend", "environment": "development"}
{"timestamp": "2025-07-06T12:08:49.647965Z", "level": "ERROR", "logger": "adogent", "message": "Error logging test message", "module": "main", "function": "lifespan", "line": 34, "thread": 281472866709536, "thread_name": "MainThread", "process": 11, "service": "adogent-backend", "environment": "development"}
{"timestamp": "2025-07-06T12:08:49.648252Z", "level": "ERROR", "logger": "adogent", "message": "Error logging test message", "module": "main", "function": "lifespan", "line": 34, "thread": 281473066876960, "thread_name": "MainThread", "process": 12, "service": "adogent-backend", "environment": "development"}
{"timestamp": "2025-07-06T12:08:49.648439Z", "level": "ERROR", "logger": "adogent", "message": "Error logging test message", "module": "main", "function": "lifespan", "line": 34, "thread": 281473576079392, "thread_name": "MainThread", "process": 10, "service": "adogent-backend", "environment": "development"}
{"timestamp": "2025-07-06T12:09:06.201386Z", "level": "ERROR", "logger": "adogent", "message": "Error: User with this email already exists", "module": "log", "function": "log_error", "line": 331, "thread": 281473066876960, "thread_name": "MainThread", "process": 12, "service": "adogent-backend", "environment": "development", "exception": {"type": "ConflictError", "message": "User with this email already exists", "traceback": "Traceback (most recent call last):\n  File \"/usr/app/app/services/auth_service.py\", line 68, in register_user\n    new_user = await self.user_service.create_user(user_data)\n               ^^^^^^^^^^^^^^^^^^^^^^^^^^^^^^^^^^^^^^^^^^^^^^\n  File \"/usr/app/app/services/user_service.py\", line 57, in create_user\n    raise ConflictError(\"User with this email already exists\")\napp.utils.exceptions.ConflictError: User with this email already exists"}}
{"timestamp": "2025-07-06T12:09:48.484163Z", "level": "ERROR", "logger": "adogent", "message": "Registration error: 1 validation error for AuthTokenResponse\nuser.updated_at\n  Field required [type=missing, input_value=UserResponse(email='bolex...59915), last_login=None), input_type=UserResponse]\n    For further information visit https://errors.pydantic.dev/2.11/v/missing", "module": "auth", "function": "register_user", "line": 78, "thread": 281473364774944, "thread_name": "MainThread", "process": 13, "service": "adogent-backend", "environment": "development"}
{"timestamp": "2025-07-06T12:15:21.165135Z", "level": "ERROR", "logger": "adogent", "message": "Error logging test message", "module": "main", "function": "lifespan", "line": 34, "thread": 281472865816608, "thread_name": "MainThread", "process": 13, "service": "adogent-backend", "environment": "development"}
{"timestamp": "2025-07-06T12:15:21.175424Z", "level": "ERROR", "logger": "adogent", "message": "Error logging test message", "module": "main", "function": "lifespan", "line": 34, "thread": 281473317380128, "thread_name": "MainThread", "process": 11, "service": "adogent-backend", "environment": "development"}
{"timestamp": "2025-07-06T12:15:21.177805Z", "level": "ERROR", "logger": "adogent", "message": "Error logging test message", "module": "main", "function": "lifespan", "line": 34, "thread": 281473853784096, "thread_name": "MainThread", "process": 10, "service": "adogent-backend", "environment": "development"}
{"timestamp": "2025-07-06T12:15:21.181102Z", "level": "ERROR", "logger": "adogent", "message": "Error logging test message", "module": "main", "function": "lifespan", "line": 34, "thread": 281473176981536, "thread_name": "MainThread", "process": 12, "service": "adogent-backend", "environment": "development"}
{"timestamp": "2025-07-06T12:15:26.941205Z", "level": "ERROR", "logger": "adogent", "message": "Error: User with this email already exists", "module": "log", "function": "log_error", "line": 331, "thread": 281473176981536, "thread_name": "MainThread", "process": 12, "service": "adogent-backend", "environment": "development", "exception": {"type": "ConflictError", "message": "User with this email already exists", "traceback": "Traceback (most recent call last):\n  File \"/usr/app/app/services/auth_service.py\", line 68, in register_user\n    new_user = await self.user_service.create_user(user_data)\n               ^^^^^^^^^^^^^^^^^^^^^^^^^^^^^^^^^^^^^^^^^^^^^^\n  File \"/usr/app/app/services/user_service.py\", line 57, in create_user\n    raise ConflictError(\"User with this email already exists\")\napp.utils.exceptions.ConflictError: User with this email already exists"}}
{"timestamp": "2025-07-06T12:16:12.047197Z", "level": "ERROR", "logger": "adogent", "message": "Login error: 1 validation error for AuthTokenResponse\nuser.updated_at\n  Field required [type=missing, input_value=UserResponse(email='bolex..., 6, 12, 16, 12, 23442)), input_type=UserResponse]\n    For further information visit https://errors.pydantic.dev/2.11/v/missing", "module": "auth", "function": "login_user", "line": 132, "thread": 281473176981536, "thread_name": "MainThread", "process": 12, "service": "adogent-backend", "environment": "development"}
{"timestamp": "2025-07-06T12:20:58.025093Z", "level": "ERROR", "logger": "adogent", "message": "Error logging test message", "module": "main", "function": "lifespan", "line": 34, "thread": 281473124524064, "thread_name": "MainThread", "process": 12, "service": "adogent-backend", "environment": "development"}
{"timestamp": "2025-07-06T12:20:58.026185Z", "level": "ERROR", "logger": "adogent", "message": "Error logging test message", "module": "main", "function": "lifespan", "line": 34, "thread": 281472920637472, "thread_name": "MainThread", "process": 10, "service": "adogent-backend", "environment": "development"}
{"timestamp": "2025-07-06T12:20:58.026623Z", "level": "ERROR", "logger": "adogent", "message": "Error logging test message", "module": "main", "function": "lifespan", "line": 34, "thread": 281473454628896, "thread_name": "MainThread", "process": 13, "service": "adogent-backend", "environment": "development"}
{"timestamp": "2025-07-06T12:20:58.028115Z", "level": "ERROR", "logger": "adogent", "message": "Error logging test message", "module": "main", "function": "lifespan", "line": 34, "thread": 281472944635936, "thread_name": "MainThread", "process": 11, "service": "adogent-backend", "environment": "development"}
{"timestamp": "2025-07-06T12:21:06.217789Z", "level": "ERROR", "logger": "adogent", "message": "Login error: 1 validation error for AuthTokenResponse\nuser.updated_at\n  Field required [type=missing, input_value=UserResponse(email='bolex..., 6, 12, 21, 6, 195925)), input_type=UserResponse]\n    For further information visit https://errors.pydantic.dev/2.11/v/missing", "module": "auth", "function": "login_user", "line": 132, "thread": 281473454628896, "thread_name": "MainThread", "process": 13, "service": "adogent-backend", "environment": "development"}
{"timestamp": "2025-07-06T12:26:37.186167Z", "level": "ERROR", "logger": "adogent", "message": "Error logging test message", "module": "main", "function": "lifespan", "line": 34, "thread": 281473284120608, "thread_name": "MainThread", "process": 10, "service": "adogent-backend", "environment": "development"}
{"timestamp": "2025-07-06T12:26:37.187027Z", "level": "ERROR", "logger": "adogent", "message": "Error logging test message", "module": "main", "function": "lifespan", "line": 34, "thread": 281473398345760, "thread_name": "MainThread", "process": 12, "service": "adogent-backend", "environment": "development"}
{"timestamp": "2025-07-06T12:26:37.189883Z", "level": "ERROR", "logger": "adogent", "message": "Error logging test message", "module": "main", "function": "lifespan", "line": 34, "thread": 281473750528032, "thread_name": "MainThread", "process": 13, "service": "adogent-backend", "environment": "development"}
{"timestamp": "2025-07-06T12:26:37.190795Z", "level": "ERROR", "logger": "adogent", "message": "Error logging test message", "module": "main", "function": "lifespan", "line": 34, "thread": 281473095897120, "thread_name": "MainThread", "process": 11, "service": "adogent-backend", "environment": "development"}
{"timestamp": "2025-07-06T12:28:28.889079Z", "level": "ERROR", "logger": "adogent", "message": "Error bootstrapping admin user: User with this email already exists", "module": "users", "function": "bootstrap_admin_user", "line": 81, "thread": 281473750528032, "thread_name": "MainThread", "process": 13, "service": "adogent-backend", "environment": "development"}
{"timestamp": "2025-07-06T12:35:25.608211Z", "level": "ERROR", "logger": "adogent", "message": "Error logging test message", "module": "main", "function": "lifespan", "line": 34, "thread": 281473357795360, "thread_name": "MainThread", "process": 12, "service": "adogent-backend", "environment": "development"}
{"timestamp": "2025-07-06T12:35:25.608555Z", "level": "ERROR", "logger": "adogent", "message": "Error logging test message", "module": "main", "function": "lifespan", "line": 34, "thread": 281473747509280, "thread_name": "MainThread", "process": 14, "service": "adogent-backend", "environment": "development"}
{"timestamp": "2025-07-06T12:35:25.610283Z", "level": "ERROR", "logger": "adogent", "message": "Error logging test message", "module": "main", "function": "lifespan", "line": 34, "thread": 281473193394208, "thread_name": "MainThread", "process": 13, "service": "adogent-backend", "environment": "development"}
{"timestamp": "2025-07-06T12:35:25.611610Z", "level": "ERROR", "logger": "adogent", "message": "Error logging test message", "module": "main", "function": "lifespan", "line": 34, "thread": 281473489244192, "thread_name": "MainThread", "process": 11, "service": "adogent-backend", "environment": "development"}
{"timestamp": "2025-07-06T12:36:33.415461Z", "level": "ERROR", "logger": "adogent", "message": "Error listing products: ProductService() takes no arguments", "module": "products", "function": "list_products", "line": 182, "thread": 281473489244192, "thread_name": "MainThread", "process": 11, "service": "adogent-backend", "environment": "development"}
{"timestamp": "2025-07-06T12:38:13.765014Z", "level": "ERROR", "logger": "adogent", "message": "Error listing users: 'dict' object has no attribute 'total'", "module": "users", "function": "list_users", "line": 307, "thread": 281473357795360, "thread_name": "MainThread", "process": 12, "service": "adogent-backend", "environment": "development"}
{"timestamp": "2025-07-06T12:38:13.771531Z", "level": "ERROR", "logger": "adogent", "message": "Request failed: GET /api/v1/users/ - 'NoneType' object has no attribute 'HTTP_500_INTERNAL_SERVER_ERROR'", "module": "main", "function": "logging_middleware", "line": 140, "thread": 281473357795360, "thread_name": "MainThread", "process": 12, "service": "adogent-backend", "environment": "development", "exception": {"type": "AttributeError", "message": "'NoneType' object has no attribute 'HTTP_500_INTERNAL_SERVER_ERROR'", "traceback": "Traceback (most recent call last):\n  File \"/usr/local/lib/python3.12/site-packages/starlette/middleware/base.py\", line 148, in call_next\n    message = await recv_stream.receive()\n              ^^^^^^^^^^^^^^^^^^^^^^^^^^^\n  File \"/usr/local/lib/python3.12/site-packages/anyio/streams/memory.py\", line 126, in receive\n    raise EndOfStream from None\nanyio.EndOfStream\n\nDuring handling of the above exception, another exception occurred:\n\nTraceback (most recent call last):\n  File \"/usr/app/app/main.py\", line 107, in logging_middleware\n    response = await call_next(request)\n               ^^^^^^^^^^^^^^^^^^^^^^^^\n  File \"/usr/local/lib/python3.12/site-packages/starlette/middleware/base.py\", line 156, in call_next\n    raise app_exc\n  File \"/usr/local/lib/python3.12/site-packages/starlette/middleware/base.py\", line 141, in coro\n    await self.app(scope, receive_or_disconnect, send_no_error)\n  File \"/usr/local/lib/python3.12/site-packages/starlette/middleware/exceptions.py\", line 62, in __call__\n    await wrap_app_handling_exceptions(self.app, conn)(scope, receive, send)\n  File \"/usr/local/lib/python3.12/site-packages/starlette/_exception_handler.py\", line 53, in wrapped_app\n    raise exc\n  File \"/usr/local/lib/python3.12/site-packages/starlette/_exception_handler.py\", line 42, in wrapped_app\n    await app(scope, receive, sender)\n  File \"/usr/local/lib/python3.12/site-packages/starlette/routing.py\", line 714, in __call__\n    await self.middleware_stack(scope, receive, send)\n  File \"/usr/local/lib/python3.12/site-packages/starlette/routing.py\", line 734, in app\n    await route.handle(scope, receive, send)\n  File \"/usr/local/lib/python3.12/site-packages/starlette/routing.py\", line 288, in handle\n    await self.app(scope, receive, send)\n  File \"/usr/local/lib/python3.12/site-packages/starlette/routing.py\", line 76, in app\n    await wrap_app_handling_exceptions(app, request)(scope, receive, send)\n  File \"/usr/local/lib/python3.12/site-packages/starlette/_exception_handler.py\", line 53, in wrapped_app\n    raise exc\n  File \"/usr/local/lib/python3.12/site-packages/starlette/_exception_handler.py\", line 42, in wrapped_app\n    await app(scope, receive, sender)\n  File \"/usr/local/lib/python3.12/site-packages/starlette/routing.py\", line 73, in app\n    response = await f(request)\n               ^^^^^^^^^^^^^^^^\n  File \"/usr/local/lib/python3.12/site-packages/fastapi/routing.py\", line 301, in app\n    raw_response = await run_endpoint_function(\n                   ^^^^^^^^^^^^^^^^^^^^^^^^^^^^\n  File \"/usr/local/lib/python3.12/site-packages/fastapi/routing.py\", line 212, in run_endpoint_function\n    return await dependant.call(**values)\n           ^^^^^^^^^^^^^^^^^^^^^^^^^^^^^^\n  File \"/usr/app/app/api/users.py\", line 309, in list_users\n    status_code=status.HTTP_500_INTERNAL_SERVER_ERROR,\n                ^^^^^^^^^^^^^^^^^^^^^^^^^^^^^^^^^^^^^\nAttributeError: 'NoneType' object has no attribute 'HTTP_500_INTERNAL_SERVER_ERROR'"}, "request_id": "b9b2d244-76c1-4344-97e7-b6c9f413d367", "endpoint": "/api/v1/users/", "method": "GET", "response_time": 0.10119462013244629}
{"timestamp": "2025-07-06T12:47:07.163770Z", "level": "ERROR", "logger": "adogent", "message": "Error logging test message", "module": "main", "function": "lifespan", "line": 34, "thread": 281472865996832, "thread_name": "MainThread", "process": 12, "service": "adogent-backend", "environment": "development"}
{"timestamp": "2025-07-06T12:47:07.163900Z", "level": "ERROR", "logger": "adogent", "message": "Error logging test message", "module": "main", "function": "lifespan", "line": 34, "thread": 281473408888864, "thread_name": "MainThread", "process": 10, "service": "adogent-backend", "environment": "development"}
{"timestamp": "2025-07-06T12:47:07.163927Z", "level": "ERROR", "logger": "adogent", "message": "Error logging test message", "module": "main", "function": "lifespan", "line": 34, "thread": 281473857835040, "thread_name": "MainThread", "process": 9, "service": "adogent-backend", "environment": "development"}
{"timestamp": "2025-07-06T12:47:07.164562Z", "level": "ERROR", "logger": "adogent", "message": "Error logging test message", "module": "main", "function": "lifespan", "line": 34, "thread": 281473852215328, "thread_name": "MainThread", "process": 11, "service": "adogent-backend", "environment": "development"}
{"timestamp": "2025-07-06T12:47:12.325749Z", "level": "ERROR", "logger": "adogent", "message": "Error listing users: 'dict' object has no attribute 'total'", "module": "users", "function": "list_users", "line": 314, "thread": 281473852215328, "thread_name": "MainThread", "process": 11, "service": "adogent-backend", "environment": "development"}
{"timestamp": "2025-07-06T12:48:08.115917Z", "level": "ERROR", "logger": "adogent", "message": "Error listing products: 'dict' object has no attribute 'total'", "module": "products", "function": "list_products", "line": 187, "thread": 281473857835040, "thread_name": "MainThread", "process": 9, "service": "adogent-backend", "environment": "development"}
{"timestamp": "2025-07-06T12:50:33.079518Z", "level": "ERROR", "logger": "adogent", "message": "Error logging test message", "module": "main", "function": "lifespan", "line": 34, "thread": 281473114456096, "thread_name": "MainThread", "process": 10, "service": "adogent-backend", "environment": "development"}
{"timestamp": "2025-07-06T12:50:33.079571Z", "level": "ERROR", "logger": "adogent", "message": "Error logging test message", "module": "main", "function": "lifespan", "line": 34, "thread": 281473011453984, "thread_name": "MainThread", "process": 11, "service": "adogent-backend", "environment": "development"}
{"timestamp": "2025-07-06T12:50:33.079614Z", "level": "ERROR", "logger": "adogent", "message": "Error logging test message", "module": "main", "function": "lifespan", "line": 34, "thread": 281473128333344, "thread_name": "MainThread", "process": 12, "service": "adogent-backend", "environment": "development"}
{"timestamp": "2025-07-06T12:50:33.080300Z", "level": "ERROR", "logger": "adogent", "message": "Error logging test message", "module": "main", "function": "lifespan", "line": 34, "thread": 281473358168096, "thread_name": "MainThread", "process": 13, "service": "adogent-backend", "environment": "development"}
{"timestamp": "2025-07-06T12:50:38.248552Z", "level": "ERROR", "logger": "adogent", "message": "Error listing products: 2 validation errors for PaginatedProductResponseResponse\nitems\n  Field required [type=missing, input_value={'products': [], 'total':... 'size': 20, 'pages': 0}, input_type=dict]\n    For further information visit https://errors.pydantic.dev/2.11/v/missing\nmetadata\n  Field required [type=missing, input_value={'products': [], 'total':... 'size': 20, 'pages': 0}, input_type=dict]\n    For further information visit https://errors.pydantic.dev/2.11/v/missing", "module": "products", "function": "list_products", "line": 187, "thread": 281473358168096, "thread_name": "MainThread", "process": 13, "service": "adogent-backend", "environment": "development"}

{"timestamp": "2025-07-06T12:52:17.862143Z", "level": "ERROR", "logger": "adogent", "message": "Error listing products: 2 validation errors for PaginatedProductResponseResponse\nitems\n  Field required [type=missing, input_value={'products': [], 'total':... 'size': 20, 'pages': 0}, input_type=dict]\n    For further information visit https://errors.pydantic.dev/2.11/v/missing\nmetadata\n  Field required [type=missing, input_value={'products': [], 'total':... 'size': 20, 'pages': 0}, input_type=dict]\n    For further information visit https://errors.pydantic.dev/2.11/v/missing", "module": "products", "function": "list_products", "line": 187, "thread": 281473358168096, "thread_name": "MainThread", "process": 13, "service": "adogent-backend", "environment": "development"}
{"timestamp": "2025-07-06T12:57:45.462671Z", "level": "ERROR", "logger": "adogent", "message": "Error logging test message", "module": "main", "function": "lifespan", "line": 34, "thread": 281473299103776, "thread_name": "MainThread", "process": 13, "service": "adogent-backend", "environment": "development"}
{"timestamp": "2025-07-06T12:57:45.462875Z", "level": "ERROR", "logger": "adogent", "message": "Error logging test message", "module": "main", "function": "lifespan", "line": 34, "thread": 281473505734688, "thread_name": "MainThread", "process": 11, "service": "adogent-backend", "environment": "development"}
{"timestamp": "2025-07-06T12:57:45.463005Z", "level": "ERROR", "logger": "adogent", "message": "Error logging test message", "module": "main", "function": "lifespan", "line": 34, "thread": 281473258299424, "thread_name": "MainThread", "process": 10, "service": "adogent-backend", "environment": "development"}
{"timestamp": "2025-07-06T12:57:45.464592Z", "level": "ERROR", "logger": "adogent", "message": "Error logging test message", "module": "main", "function": "lifespan", "line": 34, "thread": 281472834261024, "thread_name": "MainThread", "process": 12, "service": "adogent-backend", "environment": "development"}
{"timestamp": "2025-07-06T14:19:00.368942Z", "level": "ERROR", "logger": "adogent", "message": "Error logging test message", "module": "main", "function": "lifespan", "line": 34, "thread": 281473761779744, "thread_name": "MainThread", "process": 11, "service": "adogent-backend", "environment": "development"}
{"timestamp": "2025-07-06T14:19:00.369002Z", "level": "ERROR", "logger": "adogent", "message": "Error logging test message", "module": "main", "function": "lifespan", "line": 34, "thread": 281473450344480, "thread_name": "MainThread", "process": 12, "service": "adogent-backend", "environment": "development"}
{"timestamp": "2025-07-06T14:19:00.369120Z", "level": "ERROR", "logger": "adogent", "message": "Error logging test message", "module": "main", "function": "lifespan", "line": 34, "thread": 281472888061984, "thread_name": "MainThread", "process": 13, "service": "adogent-backend", "environment": "development"}
{"timestamp": "2025-07-06T14:19:00.369164Z", "level": "ERROR", "logger": "adogent", "message": "Error logging test message", "module": "main", "function": "lifespan", "line": 34, "thread": 281473704853536, "thread_name": "MainThread", "process": 10, "service": "adogent-backend", "environment": "development"}
{"timestamp": "2025-07-06T14:20:33.976063Z", "level": "ERROR", "logger": "adogent", "message": "Error creating category: property 'is_active' of 'Category' object has no setter", "module": "category", "function": "create_category", "line": 58, "thread": 281472888061984, "thread_name": "MainThread", "process": 13, "service": "adogent-backend", "environment": "development"}
{"timestamp": "2025-07-06T14:27:07.587495Z", "level": "ERROR", "logger": "adogent", "message": "Error logging test message", "module": "main", "function": "lifespan", "line": 34, "thread": 281473248165920, "thread_name": "MainThread", "process": 11, "service": "adogent-backend", "environment": "development"}
{"timestamp": "2025-07-06T14:27:07.588090Z", "level": "ERROR", "logger": "adogent", "message": "Error logging test message", "module": "main", "function": "lifespan", "line": 34, "thread": 281473571422240, "thread_name": "MainThread", "process": 12, "service": "adogent-backend", "environment": "development"}
{"timestamp": "2025-07-06T14:27:07.588232Z", "level": "ERROR", "logger": "adogent", "message": "Error logging test message", "module": "main", "function": "lifespan", "line": 34, "thread": 281473669373984, "thread_name": "MainThread", "process": 13, "service": "adogent-backend", "environment": "development"}
{"timestamp": "2025-07-06T14:27:07.591562Z", "level": "ERROR", "logger": "adogent", "message": "Error logging test message", "module": "main", "function": "lifespan", "line": 34, "thread": 281473042505760, "thread_name": "MainThread", "process": 14, "service": "adogent-backend", "environment": "development"}
{"timestamp": "2025-07-06T14:27:27.417004Z", "level": "ERROR", "logger": "adogent", "message": "Error logging test message", "module": "main", "function": "lifespan", "line": 34, "thread": 281473818591264, "thread_name": "MainThread", "process": 13, "service": "adogent-backend", "environment": "development"}
{"timestamp": "2025-07-06T14:27:27.427298Z", "level": "ERROR", "logger": "adogent", "message": "Error logging test message", "module": "main", "function": "lifespan", "line": 34, "thread": 281473001967648, "thread_name": "MainThread", "process": 12, "service": "adogent-backend", "environment": "development"}
{"timestamp": "2025-07-06T14:27:27.431390Z", "level": "ERROR", "logger": "adogent", "message": "Error logging test message", "module": "main", "function": "lifespan", "line": 34, "thread": 281473250762784, "thread_name": "MainThread", "process": 10, "service": "adogent-backend", "environment": "development"}
{"timestamp": "2025-07-06T14:27:27.435863Z", "level": "ERROR", "logger": "adogent", "message": "Error logging test message", "module": "main", "function": "lifespan", "line": 34, "thread": 281473878036512, "thread_name": "MainThread", "process": 11, "service": "adogent-backend", "environment": "development"}
{"timestamp": "2025-07-06T14:33:01.374632Z", "level": "ERROR", "logger": "adogent", "message": "Error creating product: 'tags' is an invalid keyword argument for Product", "module": "products", "function": "create_product", "line": 45, "thread": 281473250762784, "thread_name": "MainThread", "process": 10, "service": "adogent-backend", "environment": "development"}
{"timestamp": "2025-07-06T14:36:47.402237Z", "level": "ERROR", "logger": "adogent", "message": "Error logging test message", "module": "main", "function": "lifespan", "line": 34, "thread": 281473353650208, "thread_name": "MainThread", "process": 10, "service": "adogent-backend", "environment": "development"}
{"timestamp": "2025-07-06T14:36:47.403072Z", "level": "ERROR", "logger": "adogent", "message": "Error logging test message", "module": "main", "function": "lifespan", "line": 34, "thread": 281473039286304, "thread_name": "MainThread", "process": 12, "service": "adogent-backend", "environment": "development"}
{"timestamp": "2025-07-06T14:36:47.407813Z", "level": "ERROR", "logger": "adogent", "message": "Error logging test message", "module": "main", "function": "lifespan", "line": 34, "thread": 281473717055520, "thread_name": "MainThread", "process": 13, "service": "adogent-backend", "environment": "development"}
{"timestamp": "2025-07-06T14:36:47.413621Z", "level": "ERROR", "logger": "adogent", "message": "Error logging test message", "module": "main", "function": "lifespan", "line": 34, "thread": 281473837547552, "thread_name": "MainThread", "process": 11, "service": "adogent-backend", "environment": "development"}
{"timestamp": "2025-07-06T14:37:01.972196Z", "level": "ERROR", "logger": "adogent", "message": "Request failed: POST /api/v1/products/ - 2 validation errors:\n  {'type': 'enum', 'loc': ('response', 'status'), 'msg': \"Input should be 'DRAFT', 'ACTIVE', 'ARCHIVED' or 'OUT_OF_STOCK'\", 'input': <ProductStatus.ACTIVE: 'active'>, 'ctx': {'expected': \"'DRAFT', 'ACTIVE', 'ARCHIVED' or 'OUT_OF_STOCK'\"}}\n  {'type': 'enum', 'loc': ('response', 'condition'), 'msg': \"Input should be 'NEW', 'LIKE_NEW', 'EXCELLENT', 'GOOD' or 'FAIR'\", 'input': <ProductCondition.EXCELLENT: 'excellent'>, 'ctx': {'expected': \"'NEW', 'LIKE_NEW', 'EXCELLENT', 'GOOD' or 'FAIR'\"}}\n", "module": "main", "function": "logging_middleware", "line": 140, "thread": 281473837547552, "thread_name": "MainThread", "process": 11, "service": "adogent-backend", "environment": "development", "exception": {"type": "ResponseValidationError", "message": "2 validation errors:\n  {'type': 'enum', 'loc': ('response', 'status'), 'msg': \"Input should be 'DRAFT', 'ACTIVE', 'ARCHIVED' or 'OUT_OF_STOCK'\", 'input': <ProductStatus.ACTIVE: 'active'>, 'ctx': {'expected': \"'DRAFT', 'ACTIVE', 'ARCHIVED' or 'OUT_OF_STOCK'\"}}\n  {'type': 'enum', 'loc': ('response', 'condition'), 'msg': \"Input should be 'NEW', 'LIKE_NEW', 'EXCELLENT', 'GOOD' or 'FAIR'\", 'input': <ProductCondition.EXCELLENT: 'excellent'>, 'ctx': {'expected': \"'NEW', 'LIKE_NEW', 'EXCELLENT', 'GOOD' or 'FAIR'\"}}\n", "traceback": "Traceback (most recent call last):\n  File \"/usr/local/lib/python3.12/site-packages/starlette/middleware/base.py\", line 148, in call_next\n    message = await recv_stream.receive()\n              ^^^^^^^^^^^^^^^^^^^^^^^^^^^\n  File \"/usr/local/lib/python3.12/site-packages/anyio/streams/memory.py\", line 126, in receive\n    raise EndOfStream from None\nanyio.EndOfStream\n\nDuring handling of the above exception, another exception occurred:\n\nTraceback (most recent call last):\n  File \"/usr/app/app/main.py\", line 107, in logging_middleware\n    response = await call_next(request)\n               ^^^^^^^^^^^^^^^^^^^^^^^^\n  File \"/usr/local/lib/python3.12/site-packages/starlette/middleware/base.py\", line 156, in call_next\n    raise app_exc\n  File \"/usr/local/lib/python3.12/site-packages/starlette/middleware/base.py\", line 141, in coro\n    await self.app(scope, receive_or_disconnect, send_no_error)\n  File \"/usr/local/lib/python3.12/site-packages/starlette/middleware/exceptions.py\", line 62, in __call__\n    await wrap_app_handling_exceptions(self.app, conn)(scope, receive, send)\n  File \"/usr/local/lib/python3.12/site-packages/starlette/_exception_handler.py\", line 53, in wrapped_app\n    raise exc\n  File \"/usr/local/lib/python3.12/site-packages/starlette/_exception_handler.py\", line 42, in wrapped_app\n    await app(scope, receive, sender)\n  File \"/usr/local/lib/python3.12/site-packages/starlette/routing.py\", line 714, in __call__\n    await self.middleware_stack(scope, receive, send)\n  File \"/usr/local/lib/python3.12/site-packages/starlette/routing.py\", line 734, in app\n    await route.handle(scope, receive, send)\n  File \"/usr/local/lib/python3.12/site-packages/starlette/routing.py\", line 288, in handle\n    await self.app(scope, receive, send)\n  File \"/usr/local/lib/python3.12/site-packages/starlette/routing.py\", line 76, in app\n    await wrap_app_handling_exceptions(app, request)(scope, receive, send)\n  File \"/usr/local/lib/python3.12/site-packages/starlette/_exception_handler.py\", line 53, in wrapped_app\n    raise exc\n  File \"/usr/local/lib/python3.12/site-packages/starlette/_exception_handler.py\", line 42, in wrapped_app\n    await app(scope, receive, sender)\n  File \"/usr/local/lib/python3.12/site-packages/starlette/routing.py\", line 73, in app\n    response = await f(request)\n               ^^^^^^^^^^^^^^^^\n  File \"/usr/local/lib/python3.12/site-packages/fastapi/routing.py\", line 327, in app\n    content = await serialize_response(\n              ^^^^^^^^^^^^^^^^^^^^^^^^^\n  File \"/usr/local/lib/python3.12/site-packages/fastapi/routing.py\", line 176, in serialize_response\n    raise ResponseValidationError(\nfastapi.exceptions.ResponseValidationError: 2 validation errors:\n  {'type': 'enum', 'loc': ('response', 'status'), 'msg': \"Input should be 'DRAFT', 'ACTIVE', 'ARCHIVED' or 'OUT_OF_STOCK'\", 'input': <ProductStatus.ACTIVE: 'active'>, 'ctx': {'expected': \"'DRAFT', 'ACTIVE', 'ARCHIVED' or 'OUT_OF_STOCK'\"}}\n  {'type': 'enum', 'loc': ('response', 'condition'), 'msg': \"Input should be 'NEW', 'LIKE_NEW', 'EXCELLENT', 'GOOD' or 'FAIR'\", 'input': <ProductCondition.EXCELLENT: 'excellent'>, 'ctx': {'expected': \"'NEW', 'LIKE_NEW', 'EXCELLENT', 'GOOD' or 'FAIR'\"}}\n"}, "request_id": "0bc03b9a-8aae-439a-bd50-337eed8b4847", "endpoint": "/api/v1/products/", "method": "POST", "response_time": 0.10071420669555664}
{"timestamp": "2025-07-06T14:39:12.348473Z", "level": "ERROR", "logger": "adogent", "message": "Error listing products: 2 validation errors for ProductListResponse\nproducts.0.status\n  Input should be 'DRAFT', 'ACTIVE', 'ARCHIVED' or 'OUT_OF_STOCK' [type=enum, input_value=<ProductStatus.ACTIVE: 'active'>, input_type=ProductStatus]\n    For further information visit https://errors.pydantic.dev/2.11/v/enum\nproducts.0.condition\n  Input should be 'NEW', 'LIKE_NEW', 'EXCELLENT', 'GOOD' or 'FAIR' [type=enum, input_value=<ProductCondition.EXCELLENT: 'excellent'>, input_type=ProductCondition]\n    For further information visit https://errors.pydantic.dev/2.11/v/enum", "module": "products", "function": "list_products", "line": 206, "thread": 281473837547552, "thread_name": "MainThread", "process": 11, "service": "adogent-backend", "environment": "development"}
{"timestamp": "2025-07-06T14:41:16.442845Z", "level": "ERROR", "logger": "adogent", "message": "Error logging test message", "module": "main", "function": "lifespan", "line": 34, "thread": 281472924946464, "thread_name": "MainThread", "process": 12, "service": "adogent-backend", "environment": "development"}
{"timestamp": "2025-07-06T14:41:16.443289Z", "level": "ERROR", "logger": "adogent", "message": "Error logging test message", "module": "main", "function": "lifespan", "line": 34, "thread": 281473512194080, "thread_name": "MainThread", "process": 10, "service": "adogent-backend", "environment": "development"}
{"timestamp": "2025-07-06T14:41:16.443351Z", "level": "ERROR", "logger": "adogent", "message": "Error logging test message", "module": "main", "function": "lifespan", "line": 34, "thread": 281473377533984, "thread_name": "MainThread", "process": 13, "service": "adogent-backend", "environment": "development"}
{"timestamp": "2025-07-06T14:41:16.443585Z", "level": "ERROR", "logger": "adogent", "message": "Error logging test message", "module": "main", "function": "lifespan", "line": 34, "thread": 281472927432736, "thread_name": "MainThread", "process": 11, "service": "adogent-backend", "environment": "development"}
{"timestamp": "2025-07-06T14:43:15.934462Z", "level": "ERROR", "logger": "adogent", "message": "Error creating product: (sqlalchemy.dialects.postgresql.asyncpg.Error) <class 'asyncpg.exceptions.InvalidTextRepresentationError'>: invalid input value for enum productstatus: \"active\"\n[SQL: INSERT INTO products (name, slug, description, short_description, category_id, price, compare_at_price, cost_price, currency, sku, barcode, quantity, low_stock_threshold, status, is_featured, is_visible, weight, weight_unit, dimensions, is_second_hand, condition, condition_description, meta_title, meta_description, meta_keywords, search_vector, ai_summary, id, created_at, updated_at, deleted_at, is_deleted) VALUES ($1::VARCHAR, $2::VARCHAR, $3::VARCHAR, $4::VARCHAR, $5::UUID, $6::FLOAT, $7::FLOAT, $8::FLOAT, $9::VARCHAR, $10::VARCHAR, $11::VARCHAR, $12::INTEGER, $13::INTEGER, $14::productstatus, $15::BOOLEAN, $16::BOOLEAN, $17::FLOAT, $18::VARCHAR, $19::JSONB, $20::BOOLEAN, $21::productcondition, $22::VARCHAR, $23::VARCHAR, $24::VARCHAR, $25::VARCHAR, $26::VARCHAR, $27::VARCHAR, $28::UUID, now(), now(), $29::TIMESTAMP WITHOUT TIME ZONE, $30::BOOLEAN) RETURNING products.created_at, products.updated_at]\n[parameters: ('Louis Vuitton Neverfull MM Monogram Canvas', 'louis-vuitton-neverfull-mm-monogram-canvas-brown-beige', \"This brand new Louis Vuitton Neverfull MM in the iconic Monogram canvas represents the perfect fusion of timeless elegance and contemporary functiona ... (872 characters truncated) ... As a brand new piece from Louis Vuitton's current collection, this Neverfull MM represents both impeccable style and lasting value in luxury fashion.\", 'Brand new Louis Vuitton Neverfull MM in classic Monogram canvas - the perfect luxury tote', UUID('e9823588-0cae-4d5f-97ea-cd7775ea55d0'), 2100.0, None, 1680.0, 'USD', 'LV-NEVERFULL-MM-MONO-BRN-NEW-001', '3582761234890', 3, 1, <ProductStatus.ACTIVE: 'active'>, True, True, 0.6, 'kg', '{\"length\": 32.0, \"width\": 11.0, \"height\": 29.0}', False, <ProductCondition.NEW: 'new'>, 'This Louis Vuitton Neverfull MM is brand new and in pristine condition. The Monogram canvas is flawless with no marks, scratches, or signs of wear. T ... (350 characters truncated) ...  with all original packaging and accessories, including the original dust bag, authenticity cards, care instructions, and Louis Vuitton shopping bag.', 'Louis Vuitton Neverfull MM Monogram Canvas | Brand New | ADOGENT', 'Brand new Louis Vuitton Neverfull MM in classic Monogram canvas. Authentic luxury tote bag with original packaging from ADOGENT.', 'Louis Vuitton, Neverfull, MM, Monogram canvas, brand new, authentic, luxury tote, French luxury, investment piece, LV', None, None, UUID('56a94ae2-e948-4285-a3fa-676f36bb93e1'), None, False)]\n(Background on this error at: https://sqlalche.me/e/20/dbapi)", "module": "products", "function": "create_product", "line": 45, "thread": 281472927432736, "thread_name": "MainThread", "process": 11, "service": "adogent-backend", "environment": "development"}
{"timestamp": "2025-07-06T14:49:41.771010Z", "level": "ERROR", "logger": "adogent", "message": "Error logging test message", "module": "main", "function": "lifespan", "line": 34, "thread": 281473835802656, "thread_name": "MainThread", "process": 10, "service": "adogent-backend", "environment": "development"}
{"timestamp": "2025-07-06T14:49:41.771126Z", "level": "ERROR", "logger": "adogent", "message": "Error logging test message", "module": "main", "function": "lifespan", "line": 34, "thread": 281473822658592, "thread_name": "MainThread", "process": 12, "service": "adogent-backend", "environment": "development"}
{"timestamp": "2025-07-06T14:49:41.771597Z", "level": "ERROR", "logger": "adogent", "message": "Error logging test message", "module": "main", "function": "lifespan", "line": 34, "thread": 281473498210336, "thread_name": "MainThread", "process": 13, "service": "adogent-backend", "environment": "development"}
{"timestamp": "2025-07-06T14:49:41.771912Z", "level": "ERROR", "logger": "adogent", "message": "Error logging test message", "module": "main", "function": "lifespan", "line": 34, "thread": 281473581015072, "thread_name": "MainThread", "process": 11, "service": "adogent-backend", "environment": "development"}
{"timestamp": "2025-07-06T14:49:58.280227Z", "level": "ERROR", "logger": "adogent", "message": "Error: module 'jose.jwt' has no attribute 'PyJWTError'", "module": "log", "function": "log_error", "line": 331, "thread": 281473835802656, "thread_name": "MainThread", "process": 10, "service": "adogent-backend", "environment": "development", "exception": {"type": "AttributeError", "message": "module 'jose.jwt' has no attribute 'PyJWTError'", "traceback": "Traceback (most recent call last):\n  File \"/usr/app/app/utils/security.py\", line 80, in decode_jwt_token\n    payload = jwt.decode(token, secret_key, algorithms=[algorithm])\n              ^^^^^^^^^^^^^^^^^^^^^^^^^^^^^^^^^^^^^^^^^^^^^^^^^^^^^\n  File \"/usr/local/lib/python3.12/site-packages/jose/jwt.py\", line 157, in decode\n    _validate_claims(\n  File \"/usr/local/lib/python3.12/site-packages/jose/jwt.py\", line 481, in _validate_claims\n    _validate_exp(claims, leeway=leeway)\n  File \"/usr/local/lib/python3.12/site-packages/jose/jwt.py\", line 314, in _validate_exp\n    raise ExpiredSignatureError(\"Signature has expired.\")\njose.exceptions.ExpiredSignatureError: Signature has expired.\n\nDuring handling of the above exception, another exception occurred:\n\nTraceback (most recent call last):\n  File \"/usr/app/app/services/auth_service.py\", line 236, in verify_token\n    payload = decode_jwt_token(\n              ^^^^^^^^^^^^^^^^^\n  File \"/usr/app/app/utils/security.py\", line 91, in decode_jwt_token\n    except jwt.PyJWTError as e:\n           ^^^^^^^^^^^^^^\nAttributeError: module 'jose.jwt' has no attribute 'PyJWTError'. Did you mean: 'JWTError'?"}}
{"timestamp": "2025-07-06T14:49:58.280820Z", "level": "ERROR", "logger": "adogent", "message": "Unexpected authentication error: module 'jose.jwt' has no attribute 'PyJWTError'", "module": "dependencies", "function": "get_current_user", "line": 52, "thread": 281473835802656, "thread_name": "MainThread", "process": 10, "service": "adogent-backend", "environment": "development"}
{"timestamp": "2025-07-06T14:51:10.101509Z", "level": "ERROR", "logger": "adogent", "message": "Error creating product: (sqlalchemy.dialects.postgresql.asyncpg.Error) <class 'asyncpg.exceptions.InvalidTextRepresentationError'>: invalid input value for enum productstatus: \"active\"\n[SQL: INSERT INTO products (name, slug, description, short_description, category_id, price, compare_at_price, cost_price, currency, sku, barcode, quantity, low_stock_threshold, status, is_featured, is_visible, weight, weight_unit, dimensions, is_second_hand, condition, condition_description, meta_title, meta_description, meta_keywords, search_vector, ai_summary, id, created_at, updated_at, deleted_at, is_deleted) VALUES ($1::VARCHAR, $2::VARCHAR, $3::VARCHAR, $4::VARCHAR, $5::UUID, $6::FLOAT, $7::FLOAT, $8::FLOAT, $9::VARCHAR, $10::VARCHAR, $11::VARCHAR, $12::INTEGER, $13::INTEGER, $14::productstatus, $15::BOOLEAN, $16::BOOLEAN, $17::FLOAT, $18::VARCHAR, $19::JSONB, $20::BOOLEAN, $21::productcondition, $22::VARCHAR, $23::VARCHAR, $24::VARCHAR, $25::VARCHAR, $26::VARCHAR, $27::VARCHAR, $28::UUID, now(), now(), $29::TIMESTAMP WITHOUT TIME ZONE, $30::BOOLEAN) RETURNING products.created_at, products.updated_at]\n[parameters: ('Louis Vuitton Neverfull MM Monogram Canvas', 'louis-vuitton-neverfull-mm-monogram-canvas-brown-beige', \"This brand new Louis Vuitton Neverfull MM in the iconic Monogram canvas represents the perfect fusion of timeless elegance and contemporary functiona ... (872 characters truncated) ... As a brand new piece from Louis Vuitton's current collection, this Neverfull MM represents both impeccable style and lasting value in luxury fashion.\", 'Brand new Louis Vuitton Neverfull MM in classic Monogram canvas - the perfect luxury tote', UUID('e9823588-0cae-4d5f-97ea-cd7775ea55d0'), 2100.0, None, 1680.0, 'USD', 'LV-NEVERFULL-MM-MONO-BRN-NEW-001', '3582761234890', 3, 1, <ProductStatus.ACTIVE: 'active'>, True, True, 0.6, 'kg', '{\"length\": 32.0, \"width\": 11.0, \"height\": 29.0}', False, <ProductCondition.NEW: 'new'>, 'This Louis Vuitton Neverfull MM is brand new and in pristine condition. The Monogram canvas is flawless with no marks, scratches, or signs of wear. T ... (350 characters truncated) ...  with all original packaging and accessories, including the original dust bag, authenticity cards, care instructions, and Louis Vuitton shopping bag.', 'Louis Vuitton Neverfull MM Monogram Canvas | Brand New | ADOGENT', 'Brand new Louis Vuitton Neverfull MM in classic Monogram canvas. Authentic luxury tote bag with original packaging from ADOGENT.', 'Louis Vuitton, Neverfull, MM, Monogram canvas, brand new, authentic, luxury tote, French luxury, investment piece, LV', None, None, UUID('f1360329-08cf-4382-8fb0-a31921570ad2'), None, False)]\n(Background on this error at: https://sqlalche.me/e/20/dbapi)", "module": "products", "function": "create_product", "line": 45, "thread": 281473581015072, "thread_name": "MainThread", "process": 11, "service": "adogent-backend", "environment": "development"}
{"timestamp": "2025-07-06T14:58:18.768784Z", "level": "ERROR", "logger": "adogent", "message": "Error logging test message", "module": "main", "function": "lifespan", "line": 34, "thread": 281472976048160, "thread_name": "MainThread", "process": 11, "service": "adogent-backend", "environment": "development"}
{"timestamp": "2025-07-06T14:58:18.776670Z", "level": "ERROR", "logger": "adogent", "message": "Error logging test message", "module": "main", "function": "lifespan", "line": 34, "thread": 281472881578016, "thread_name": "MainThread", "process": 14, "service": "adogent-backend", "environment": "development"}
{"timestamp": "2025-07-06T14:58:18.778758Z", "level": "ERROR", "logger": "adogent", "message": "Error logging test message", "module": "main", "function": "lifespan", "line": 34, "thread": 281473674047520, "thread_name": "MainThread", "process": 13, "service": "adogent-backend", "environment": "development"}
{"timestamp": "2025-07-06T14:58:18.778851Z", "level": "ERROR", "logger": "adogent", "message": "Error logging test message", "module": "main", "function": "lifespan", "line": 34, "thread": 281473400590368, "thread_name": "MainThread", "process": 12, "service": "adogent-backend", "environment": "development"}
{"timestamp": "2025-07-06T14:58:43.033324Z", "level": "ERROR", "logger": "adogent", "message": "Error logging test message", "module": "main", "function": "lifespan", "line": 34, "thread": 281473036369952, "thread_name": "MainThread", "process": 10, "service": "adogent-backend", "environment": "development"}
{"timestamp": "2025-07-06T14:58:43.033492Z", "level": "ERROR", "logger": "adogent", "message": "Error logging test message", "module": "main", "function": "lifespan", "line": 34, "thread": 281473090088992, "thread_name": "MainThread", "process": 12, "service": "adogent-backend", "environment": "development"}
{"timestamp": "2025-07-06T14:58:43.041608Z", "level": "ERROR", "logger": "adogent", "message": "Error logging test message", "module": "main", "function": "lifespan", "line": 34, "thread": 281473039921184, "thread_name": "MainThread", "process": 13, "service": "adogent-backend", "environment": "development"}
{"timestamp": "2025-07-06T14:58:43.048375Z", "level": "ERROR", "logger": "adogent", "message": "Error logging test message", "module": "main", "function": "lifespan", "line": 34, "thread": 281473307447328, "thread_name": "MainThread", "process": 11, "service": "adogent-backend", "environment": "development"}
{"timestamp": "2025-07-06T14:59:11.312852Z", "level": "ERROR", "logger": "adogent", "message": "Error: Mapper 'Mapper[Product(products)]' has no property 'images'.  If this property was indicated from other mappers or configure events, ensure registry.configure() has been called.", "module": "log", "function": "log_error", "line": 331, "thread": 281473090088992, "thread_name": "MainThread", "process": 12, "service": "adogent-backend", "environment": "development", "exception": {"type": "InvalidRequestError", "message": "Mapper 'Mapper[Product(products)]' has no property 'images'.  If this property was indicated from other mappers or configure events, ensure registry.configure() has been called.", "traceback": "Traceback (most recent call last):\n  File \"/usr/local/lib/python3.12/site-packages/sqlalchemy/orm/mapper.py\", line 2520, in get_property\n    return self._props[key]\n           ~~~~~~~~~~~^^^^^\nKeyError: 'images'\n\nThe above exception was the direct cause of the following exception:\n\nTraceback (most recent call last):\n  File \"/usr/app/app/services/auth_service.py\", line 249, in verify_token\n    user = await self.user_service.get_user_by_id(UUID(user_id))\n           ^^^^^^^^^^^^^^^^^^^^^^^^^^^^^^^^^^^^^^^^^^^^^^^^^^^^^\n  File \"/usr/app/app/services/user_service.py\", line 126, in get_user_by_id\n    result = await self.db.execute(query)\n             ^^^^^^^^^^^^^^^^^^^^^^^^^^^^\n  File \"/usr/local/lib/python3.12/site-packages/sqlalchemy/ext/asyncio/session.py\", line 461, in execute\n    result = await greenlet_spawn(\n             ^^^^^^^^^^^^^^^^^^^^^\n  File \"/usr/local/lib/python3.12/site-packages/sqlalchemy/util/_concurrency_py3k.py\", line 203, in greenlet_spawn\n    result = context.switch(value)\n             ^^^^^^^^^^^^^^^^^^^^^\n  File \"/usr/local/lib/python3.12/site-packages/sqlalchemy/orm/session.py\", line 2362, in execute\n    return self._execute_internal(\n           ^^^^^^^^^^^^^^^^^^^^^^^\n  File \"/usr/local/lib/python3.12/site-packages/sqlalchemy/orm/session.py\", line 2247, in _execute_internal\n    result: Result[Any] = compile_state_cls.orm_execute_statement(\n                          ^^^^^^^^^^^^^^^^^^^^^^^^^^^^^^^^^^^^^^^^\n  File \"/usr/local/lib/python3.12/site-packages/sqlalchemy/orm/context.py\", line 305, in orm_execute_statement\n    result = conn.execute(\n             ^^^^^^^^^^^^^\n  File \"/usr/local/lib/python3.12/site-packages/sqlalchemy/engine/base.py\", line 1418, in execute\n    return meth(\n           ^^^^^\n  File \"/usr/local/lib/python3.12/site-packages/sqlalchemy/sql/elements.py\", line 515, in _execute_on_connection\n    return connection._execute_clauseelement(\n           ^^^^^^^^^^^^^^^^^^^^^^^^^^^^^^^^^^\n  File \"/usr/local/lib/python3.12/site-packages/sqlalchemy/engine/base.py\", line 1632, in _execute_clauseelement\n    compiled_sql, extracted_params, cache_hit = elem._compile_w_cache(\n                                                ^^^^^^^^^^^^^^^^^^^^^^\n  File \"/usr/local/lib/python3.12/site-packages/sqlalchemy/sql/elements.py\", line 703, in _compile_w_cache\n    compiled_sql = self._compiler(\n                   ^^^^^^^^^^^^^^^\n  File \"/usr/local/lib/python3.12/site-packages/sqlalchemy/sql/elements.py\", line 316, in _compiler\n    return dialect.statement_compiler(dialect, self, **kw)\n           ^^^^^^^^^^^^^^^^^^^^^^^^^^^^^^^^^^^^^^^^^^^^^^^\n  File \"/usr/local/lib/python3.12/site-packages/sqlalchemy/sql/compiler.py\", line 1429, in __init__\n    Compiled.__init__(self, dialect, statement, **kwargs)\n  File \"/usr/local/lib/python3.12/site-packages/sqlalchemy/sql/compiler.py\", line 870, in __init__\n    self.string = self.process(self.statement, **compile_kwargs)\n                  ^^^^^^^^^^^^^^^^^^^^^^^^^^^^^^^^^^^^^^^^^^^^^^\n  File \"/usr/local/lib/python3.12/site-packages/sqlalchemy/sql/compiler.py\", line 915, in process\n    return obj._compiler_dispatch(self, **kwargs)\n           ^^^^^^^^^^^^^^^^^^^^^^^^^^^^^^^^^^^^^^\n  File \"/usr/local/lib/python3.12/site-packages/sqlalchemy/sql/visitors.py\", line 141, in _compiler_dispatch\n    return meth(self, **kw)  # type: ignore  # noqa: E501\n           ^^^^^^^^^^^^^^^^\n  File \"/usr/local/lib/python3.12/site-packages/sqlalchemy/sql/compiler.py\", line 4679, in visit_select\n    compile_state = select_stmt._compile_state_factory(\n                    ^^^^^^^^^^^^^^^^^^^^^^^^^^^^^^^^^^^\n  File \"/usr/local/lib/python3.12/site-packages/sqlalchemy/sql/base.py\", line 683, in create_for_statement\n    return klass.create_for_statement(statement, compiler, **kw)\n           ^^^^^^^^^^^^^^^^^^^^^^^^^^^^^^^^^^^^^^^^^^^^^^^^^^^^^\n  File \"/usr/local/lib/python3.12/site-packages/sqlalchemy/orm/context.py\", line 1110, in create_for_statement\n    _QueryEntity.to_compile_state(\n  File \"/usr/local/lib/python3.12/site-packages/sqlalchemy/orm/context.py\", line 2565, in to_compile_state\n    _MapperEntity(\n  File \"/usr/local/lib/python3.12/site-packages/sqlalchemy/orm/context.py\", line 2645, in __init__\n    entity._post_inspect\n  File \"/usr/local/lib/python3.12/site-packages/sqlalchemy/util/langhelpers.py\", line 1253, in __get__\n    obj.__dict__[self.__name__] = result = self.fget(obj)\n                                           ^^^^^^^^^^^^^^\n  File \"/usr/local/lib/python3.12/site-packages/sqlalchemy/orm/mapper.py\", line 2722, in _post_inspect\n    self._check_configure()\n  File \"/usr/local/lib/python3.12/site-packages/sqlalchemy/orm/mapper.py\", line 2399, in _check_configure\n    _configure_registries({self.registry}, cascade=True)\n  File \"/usr/local/lib/python3.12/site-packages/sqlalchemy/orm/mapper.py\", line 4215, in _configure_registries\n    _do_configure_registries(registries, cascade)\n  File \"/usr/local/lib/python3.12/site-packages/sqlalchemy/orm/mapper.py\", line 4256, in _do_configure_registries\n    mapper._post_configure_properties()\n  File \"/usr/local/lib/python3.12/site-packages/sqlalchemy/orm/mapper.py\", line 2416, in _post_configure_properties\n    prop.init()\n  File \"/usr/local/lib/python3.12/site-packages/sqlalchemy/orm/interfaces.py\", line 589, in init\n    self.do_init()\n  File \"/usr/local/lib/python3.12/site-packages/sqlalchemy/orm/relationships.py\", line 1647, in do_init\n    self._generate_backref()\n  File \"/usr/local/lib/python3.12/site-packages/sqlalchemy/orm/relationships.py\", line 2133, in _generate_backref\n    self._add_reverse_property(self.back_populates)\n  File \"/usr/local/lib/python3.12/site-packages/sqlalchemy/orm/relationships.py\", line 1578, in _add_reverse_property\n    other = self.mapper.get_property(key, _configure_mappers=False)\n            ^^^^^^^^^^^^^^^^^^^^^^^^^^^^^^^^^^^^^^^^^^^^^^^^^^^^^^^\n  File \"/usr/local/lib/python3.12/site-packages/sqlalchemy/orm/mapper.py\", line 2522, in get_property\n    raise sa_exc.InvalidRequestError(\nsqlalchemy.exc.InvalidRequestError: Mapper 'Mapper[Product(products)]' has no property 'images'.  If this property was indicated from other mappers or configure events, ensure registry.configure() has been called."}}
{"timestamp": "2025-07-06T14:59:11.313907Z", "level": "ERROR", "logger": "adogent", "message": "Unexpected authentication error: Mapper 'Mapper[Product(products)]' has no property 'images'.  If this property was indicated from other mappers or configure events, ensure registry.configure() has been called.", "module": "dependencies", "function": "get_current_user", "line": 52, "thread": 281473090088992, "thread_name": "MainThread", "process": 12, "service": "adogent-backend", "environment": "development"}
{"timestamp": "2025-07-06T14:59:27.749531Z", "level": "ERROR", "logger": "adogent", "message": "Error: Mapper 'Mapper[Product(products)]' has no property 'images'.  If this property was indicated from other mappers or configure events, ensure registry.configure() has been called.", "module": "log", "function": "log_error", "line": 331, "thread": 281473307447328, "thread_name": "MainThread", "process": 11, "service": "adogent-backend", "environment": "development", "exception": {"type": "InvalidRequestError", "message": "Mapper 'Mapper[Product(products)]' has no property 'images'.  If this property was indicated from other mappers or configure events, ensure registry.configure() has been called.", "traceback": "Traceback (most recent call last):\n  File \"/usr/local/lib/python3.12/site-packages/sqlalchemy/orm/mapper.py\", line 2520, in get_property\n    return self._props[key]\n           ~~~~~~~~~~~^^^^^\nKeyError: 'images'\n\nThe above exception was the direct cause of the following exception:\n\nTraceback (most recent call last):\n  File \"/usr/app/app/services/auth_service.py\", line 109, in authenticate_user\n    user = await self.user_service.get_user_by_email(login_data.email)\n           ^^^^^^^^^^^^^^^^^^^^^^^^^^^^^^^^^^^^^^^^^^^^^^^^^^^^^^^^^^^\n  File \"/usr/app/app/services/user_service.py\", line 145, in get_user_by_email\n    result = await self.db.execute(query)\n             ^^^^^^^^^^^^^^^^^^^^^^^^^^^^\n  File \"/usr/local/lib/python3.12/site-packages/sqlalchemy/ext/asyncio/session.py\", line 461, in execute\n    result = await greenlet_spawn(\n             ^^^^^^^^^^^^^^^^^^^^^\n  File \"/usr/local/lib/python3.12/site-packages/sqlalchemy/util/_concurrency_py3k.py\", line 203, in greenlet_spawn\n    result = context.switch(value)\n             ^^^^^^^^^^^^^^^^^^^^^\n  File \"/usr/local/lib/python3.12/site-packages/sqlalchemy/orm/session.py\", line 2362, in execute\n    return self._execute_internal(\n           ^^^^^^^^^^^^^^^^^^^^^^^\n  File \"/usr/local/lib/python3.12/site-packages/sqlalchemy/orm/session.py\", line 2247, in _execute_internal\n    result: Result[Any] = compile_state_cls.orm_execute_statement(\n                          ^^^^^^^^^^^^^^^^^^^^^^^^^^^^^^^^^^^^^^^^\n  File \"/usr/local/lib/python3.12/site-packages/sqlalchemy/orm/context.py\", line 305, in orm_execute_statement\n    result = conn.execute(\n             ^^^^^^^^^^^^^\n  File \"/usr/local/lib/python3.12/site-packages/sqlalchemy/engine/base.py\", line 1418, in execute\n    return meth(\n           ^^^^^\n  File \"/usr/local/lib/python3.12/site-packages/sqlalchemy/sql/elements.py\", line 515, in _execute_on_connection\n    return connection._execute_clauseelement(\n           ^^^^^^^^^^^^^^^^^^^^^^^^^^^^^^^^^^\n  File \"/usr/local/lib/python3.12/site-packages/sqlalchemy/engine/base.py\", line 1632, in _execute_clauseelement\n    compiled_sql, extracted_params, cache_hit = elem._compile_w_cache(\n                                                ^^^^^^^^^^^^^^^^^^^^^^\n  File \"/usr/local/lib/python3.12/site-packages/sqlalchemy/sql/elements.py\", line 703, in _compile_w_cache\n    compiled_sql = self._compiler(\n                   ^^^^^^^^^^^^^^^\n  File \"/usr/local/lib/python3.12/site-packages/sqlalchemy/sql/elements.py\", line 316, in _compiler\n    return dialect.statement_compiler(dialect, self, **kw)\n           ^^^^^^^^^^^^^^^^^^^^^^^^^^^^^^^^^^^^^^^^^^^^^^^\n  File \"/usr/local/lib/python3.12/site-packages/sqlalchemy/sql/compiler.py\", line 1429, in __init__\n    Compiled.__init__(self, dialect, statement, **kwargs)\n  File \"/usr/local/lib/python3.12/site-packages/sqlalchemy/sql/compiler.py\", line 870, in __init__\n    self.string = self.process(self.statement, **compile_kwargs)\n                  ^^^^^^^^^^^^^^^^^^^^^^^^^^^^^^^^^^^^^^^^^^^^^^\n  File \"/usr/local/lib/python3.12/site-packages/sqlalchemy/sql/compiler.py\", line 915, in process\n    return obj._compiler_dispatch(self, **kwargs)\n           ^^^^^^^^^^^^^^^^^^^^^^^^^^^^^^^^^^^^^^\n  File \"/usr/local/lib/python3.12/site-packages/sqlalchemy/sql/visitors.py\", line 141, in _compiler_dispatch\n    return meth(self, **kw)  # type: ignore  # noqa: E501\n           ^^^^^^^^^^^^^^^^\n  File \"/usr/local/lib/python3.12/site-packages/sqlalchemy/sql/compiler.py\", line 4679, in visit_select\n    compile_state = select_stmt._compile_state_factory(\n                    ^^^^^^^^^^^^^^^^^^^^^^^^^^^^^^^^^^^\n  File \"/usr/local/lib/python3.12/site-packages/sqlalchemy/sql/base.py\", line 683, in create_for_statement\n    return klass.create_for_statement(statement, compiler, **kw)\n           ^^^^^^^^^^^^^^^^^^^^^^^^^^^^^^^^^^^^^^^^^^^^^^^^^^^^^\n  File \"/usr/local/lib/python3.12/site-packages/sqlalchemy/orm/context.py\", line 1110, in create_for_statement\n    _QueryEntity.to_compile_state(\n  File \"/usr/local/lib/python3.12/site-packages/sqlalchemy/orm/context.py\", line 2565, in to_compile_state\n    _MapperEntity(\n  File \"/usr/local/lib/python3.12/site-packages/sqlalchemy/orm/context.py\", line 2645, in __init__\n    entity._post_inspect\n  File \"/usr/local/lib/python3.12/site-packages/sqlalchemy/util/langhelpers.py\", line 1253, in __get__\n    obj.__dict__[self.__name__] = result = self.fget(obj)\n                                           ^^^^^^^^^^^^^^\n  File \"/usr/local/lib/python3.12/site-packages/sqlalchemy/orm/mapper.py\", line 2722, in _post_inspect\n    self._check_configure()\n  File \"/usr/local/lib/python3.12/site-packages/sqlalchemy/orm/mapper.py\", line 2399, in _check_configure\n    _configure_registries({self.registry}, cascade=True)\n  File \"/usr/local/lib/python3.12/site-packages/sqlalchemy/orm/mapper.py\", line 4215, in _configure_registries\n    _do_configure_registries(registries, cascade)\n  File \"/usr/local/lib/python3.12/site-packages/sqlalchemy/orm/mapper.py\", line 4256, in _do_configure_registries\n    mapper._post_configure_properties()\n  File \"/usr/local/lib/python3.12/site-packages/sqlalchemy/orm/mapper.py\", line 2416, in _post_configure_properties\n    prop.init()\n  File \"/usr/local/lib/python3.12/site-packages/sqlalchemy/orm/interfaces.py\", line 589, in init\n    self.do_init()\n  File \"/usr/local/lib/python3.12/site-packages/sqlalchemy/orm/relationships.py\", line 1647, in do_init\n    self._generate_backref()\n  File \"/usr/local/lib/python3.12/site-packages/sqlalchemy/orm/relationships.py\", line 2133, in _generate_backref\n    self._add_reverse_property(self.back_populates)\n  File \"/usr/local/lib/python3.12/site-packages/sqlalchemy/orm/relationships.py\", line 1578, in _add_reverse_property\n    other = self.mapper.get_property(key, _configure_mappers=False)\n            ^^^^^^^^^^^^^^^^^^^^^^^^^^^^^^^^^^^^^^^^^^^^^^^^^^^^^^^\n  File \"/usr/local/lib/python3.12/site-packages/sqlalchemy/orm/mapper.py\", line 2522, in get_property\n    raise sa_exc.InvalidRequestError(\nsqlalchemy.exc.InvalidRequestError: Mapper 'Mapper[Product(products)]' has no property 'images'.  If this property was indicated from other mappers or configure events, ensure registry.configure() has been called."}}
{"timestamp": "2025-07-06T14:59:27.751448Z", "level": "ERROR", "logger": "adogent", "message": "Login error: Mapper 'Mapper[Product(products)]' has no property 'images'.  If this property was indicated from other mappers or configure events, ensure registry.configure() has been called.", "module": "auth", "function": "login_user", "line": 132, "thread": 281473307447328, "thread_name": "MainThread", "process": 11, "service": "adogent-backend", "environment": "development"}
{"timestamp": "2025-07-06T15:00:04.353979Z", "level": "ERROR", "logger": "adogent", "message": "Error: One or more mappers failed to initialize - can't proceed with initialization of other mappers. Triggering mapper: 'Mapper[ProductImage(product_images)]'. Original exception was: Mapper 'Mapper[Product(products)]' has no property 'images'.  If this property was indicated from other mappers or configure events, ensure registry.configure() has been called.", "module": "log", "function": "log_error", "line": 331, "thread": 281473090088992, "thread_name": "MainThread", "process": 12, "service": "adogent-backend", "environment": "development", "exception": {"type": "InvalidRequestError", "message": "One or more mappers failed to initialize - can't proceed with initialization of other mappers. Triggering mapper: 'Mapper[ProductImage(product_images)]'. Original exception was: Mapper 'Mapper[Product(products)]' has no property 'images'.  If this property was indicated from other mappers or configure events, ensure registry.configure() has been called.", "traceback": "Traceback (most recent call last):\n  File \"/usr/app/app/services/auth_service.py\", line 109, in authenticate_user\n    user = await self.user_service.get_user_by_email(login_data.email)\n           ^^^^^^^^^^^^^^^^^^^^^^^^^^^^^^^^^^^^^^^^^^^^^^^^^^^^^^^^^^^\n  File \"/usr/app/app/services/user_service.py\", line 145, in get_user_by_email\n    result = await self.db.execute(query)\n             ^^^^^^^^^^^^^^^^^^^^^^^^^^^^\n  File \"/usr/local/lib/python3.12/site-packages/sqlalchemy/ext/asyncio/session.py\", line 461, in execute\n    result = await greenlet_spawn(\n             ^^^^^^^^^^^^^^^^^^^^^\n  File \"/usr/local/lib/python3.12/site-packages/sqlalchemy/util/_concurrency_py3k.py\", line 203, in greenlet_spawn\n    result = context.switch(value)\n             ^^^^^^^^^^^^^^^^^^^^^\n  File \"/usr/local/lib/python3.12/site-packages/sqlalchemy/orm/session.py\", line 2362, in execute\n    return self._execute_internal(\n           ^^^^^^^^^^^^^^^^^^^^^^^\n  File \"/usr/local/lib/python3.12/site-packages/sqlalchemy/orm/session.py\", line 2247, in _execute_internal\n    result: Result[Any] = compile_state_cls.orm_execute_statement(\n                          ^^^^^^^^^^^^^^^^^^^^^^^^^^^^^^^^^^^^^^^^\n  File \"/usr/local/lib/python3.12/site-packages/sqlalchemy/orm/context.py\", line 305, in orm_execute_statement\n    result = conn.execute(\n             ^^^^^^^^^^^^^\n  File \"/usr/local/lib/python3.12/site-packages/sqlalchemy/engine/base.py\", line 1418, in execute\n    return meth(\n           ^^^^^\n  File \"/usr/local/lib/python3.12/site-packages/sqlalchemy/sql/elements.py\", line 515, in _execute_on_connection\n    return connection._execute_clauseelement(\n           ^^^^^^^^^^^^^^^^^^^^^^^^^^^^^^^^^^\n  File \"/usr/local/lib/python3.12/site-packages/sqlalchemy/engine/base.py\", line 1632, in _execute_clauseelement\n    compiled_sql, extracted_params, cache_hit = elem._compile_w_cache(\n                                                ^^^^^^^^^^^^^^^^^^^^^^\n  File \"/usr/local/lib/python3.12/site-packages/sqlalchemy/sql/elements.py\", line 703, in _compile_w_cache\n    compiled_sql = self._compiler(\n                   ^^^^^^^^^^^^^^^\n  File \"/usr/local/lib/python3.12/site-packages/sqlalchemy/sql/elements.py\", line 316, in _compiler\n    return dialect.statement_compiler(dialect, self, **kw)\n           ^^^^^^^^^^^^^^^^^^^^^^^^^^^^^^^^^^^^^^^^^^^^^^^\n  File \"/usr/local/lib/python3.12/site-packages/sqlalchemy/sql/compiler.py\", line 1429, in __init__\n    Compiled.__init__(self, dialect, statement, **kwargs)\n  File \"/usr/local/lib/python3.12/site-packages/sqlalchemy/sql/compiler.py\", line 870, in __init__\n    self.string = self.process(self.statement, **compile_kwargs)\n                  ^^^^^^^^^^^^^^^^^^^^^^^^^^^^^^^^^^^^^^^^^^^^^^\n  File \"/usr/local/lib/python3.12/site-packages/sqlalchemy/sql/compiler.py\", line 915, in process\n    return obj._compiler_dispatch(self, **kwargs)\n           ^^^^^^^^^^^^^^^^^^^^^^^^^^^^^^^^^^^^^^\n  File \"/usr/local/lib/python3.12/site-packages/sqlalchemy/sql/visitors.py\", line 141, in _compiler_dispatch\n    return meth(self, **kw)  # type: ignore  # noqa: E501\n           ^^^^^^^^^^^^^^^^\n  File \"/usr/local/lib/python3.12/site-packages/sqlalchemy/sql/compiler.py\", line 4679, in visit_select\n    compile_state = select_stmt._compile_state_factory(\n                    ^^^^^^^^^^^^^^^^^^^^^^^^^^^^^^^^^^^\n  File \"/usr/local/lib/python3.12/site-packages/sqlalchemy/sql/base.py\", line 683, in create_for_statement\n    return klass.create_for_statement(statement, compiler, **kw)\n           ^^^^^^^^^^^^^^^^^^^^^^^^^^^^^^^^^^^^^^^^^^^^^^^^^^^^^\n  File \"/usr/local/lib/python3.12/site-packages/sqlalchemy/orm/context.py\", line 1110, in create_for_statement\n    _QueryEntity.to_compile_state(\n  File \"/usr/local/lib/python3.12/site-packages/sqlalchemy/orm/context.py\", line 2565, in to_compile_state\n    _MapperEntity(\n  File \"/usr/local/lib/python3.12/site-packages/sqlalchemy/orm/context.py\", line 2645, in __init__\n    entity._post_inspect\n  File \"/usr/local/lib/python3.12/site-packages/sqlalchemy/util/langhelpers.py\", line 1253, in __get__\n    obj.__dict__[self.__name__] = result = self.fget(obj)\n                                           ^^^^^^^^^^^^^^\n  File \"/usr/local/lib/python3.12/site-packages/sqlalchemy/orm/mapper.py\", line 2722, in _post_inspect\n    self._check_configure()\n  File \"/usr/local/lib/python3.12/site-packages/sqlalchemy/orm/mapper.py\", line 2399, in _check_configure\n    _configure_registries({self.registry}, cascade=True)\n  File \"/usr/local/lib/python3.12/site-packages/sqlalchemy/orm/mapper.py\", line 4215, in _configure_registries\n    _do_configure_registries(registries, cascade)\n  File \"/usr/local/lib/python3.12/site-packages/sqlalchemy/orm/mapper.py\", line 4252, in _do_configure_registries\n    raise e\nsqlalchemy.exc.InvalidRequestError: One or more mappers failed to initialize - can't proceed with initialization of other mappers. Triggering mapper: 'Mapper[ProductImage(product_images)]'. Original exception was: Mapper 'Mapper[Product(products)]' has no property 'images'.  If this property was indicated from other mappers or configure events, ensure registry.configure() has been called."}}
{"timestamp": "2025-07-06T15:00:04.355980Z", "level": "ERROR", "logger": "adogent", "message": "Login error: One or more mappers failed to initialize - can't proceed with initialization of other mappers. Triggering mapper: 'Mapper[ProductImage(product_images)]'. Original exception was: Mapper 'Mapper[Product(products)]' has no property 'images'.  If this property was indicated from other mappers or configure events, ensure registry.configure() has been called.", "module": "auth", "function": "login_user", "line": 132, "thread": 281473090088992, "thread_name": "MainThread", "process": 12, "service": "adogent-backend", "environment": "development"}
{"timestamp": "2025-07-06T15:09:43.918102Z", "level": "ERROR", "logger": "adogent", "message": "Error logging test message", "module": "main", "function": "lifespan", "line": 34, "thread": 281473789825056, "thread_name": "MainThread", "process": 11, "service": "adogent-backend", "environment": "development"}
{"timestamp": "2025-07-06T15:09:43.918127Z", "level": "ERROR", "logger": "adogent", "message": "Error logging test message", "module": "main", "function": "lifespan", "line": 34, "thread": 281472978194464, "thread_name": "MainThread", "process": 12, "service": "adogent-backend", "environment": "development"}
{"timestamp": "2025-07-06T15:09:43.918653Z", "level": "ERROR", "logger": "adogent", "message": "Error logging test message", "module": "main", "function": "lifespan", "line": 34, "thread": 281473780867104, "thread_name": "MainThread", "process": 10, "service": "adogent-backend", "environment": "development"}
{"timestamp": "2025-07-06T15:09:43.921647Z", "level": "ERROR", "logger": "adogent", "message": "Error logging test message", "module": "main", "function": "lifespan", "line": 34, "thread": 281473237061664, "thread_name": "MainThread", "process": 13, "service": "adogent-backend", "environment": "development"}
{"timestamp": "2025-07-06T15:10:06.263017Z", "level": "ERROR", "logger": "adogent", "message": "Error logging test message", "module": "main", "function": "lifespan", "line": 34, "thread": 281472847364128, "thread_name": "MainThread", "process": 13, "service": "adogent-backend", "environment": "development"}
{"timestamp": "2025-07-06T15:10:06.272953Z", "level": "ERROR", "logger": "adogent", "message": "Error logging test message", "module": "main", "function": "lifespan", "line": 34, "thread": 281473540771872, "thread_name": "MainThread", "process": 12, "service": "adogent-backend", "environment": "development"}
{"timestamp": "2025-07-06T15:10:06.275679Z", "level": "ERROR", "logger": "adogent", "message": "Error logging test message", "module": "main", "function": "lifespan", "line": 34, "thread": 281473762164768, "thread_name": "MainThread", "process": 10, "service": "adogent-backend", "environment": "development"}
{"timestamp": "2025-07-06T15:10:06.276243Z", "level": "ERROR", "logger": "adogent", "message": "Error logging test message", "module": "main", "function": "lifespan", "line": 34, "thread": 281473244237856, "thread_name": "MainThread", "process": 11, "service": "adogent-backend", "environment": "development"}
{"timestamp": "2025-07-06T15:18:14.976915Z", "level": "ERROR", "logger": "adogent", "message": "Error logging test message", "module": "main", "function": "lifespan", "line": 34, "thread": 281473587834912, "thread_name": "MainThread", "process": 12, "service": "adogent-backend", "environment": "development"}
{"timestamp": "2025-07-06T15:18:14.977114Z", "level": "ERROR", "logger": "adogent", "message": "Error logging test message", "module": "main", "function": "lifespan", "line": 34, "thread": 281473150591008, "thread_name": "MainThread", "process": 11, "service": "adogent-backend", "environment": "development"}
{"timestamp": "2025-07-06T15:18:14.977194Z", "level": "ERROR", "logger": "adogent", "message": "Error logging test message", "module": "main", "function": "lifespan", "line": 34, "thread": 281472933609504, "thread_name": "MainThread", "process": 14, "service": "adogent-backend", "environment": "development"}
{"timestamp": "2025-07-06T15:18:14.986685Z", "level": "ERROR", "logger": "adogent", "message": "Error logging test message", "module": "main", "function": "lifespan", "line": 34, "thread": 281473588621344, "thread_name": "MainThread", "process": 13, "service": "adogent-backend", "environment": "development"}
{"timestamp": "2025-07-06T20:50:14.095356Z", "level": "ERROR", "logger": "adogent", "message": "Error logging test message", "module": "main", "function": "lifespan", "line": 34, "thread": 281473137025056, "thread_name": "MainThread", "process": 12, "service": "adogent-backend", "environment": "development"}
{"timestamp": "2025-07-06T20:50:14.095368Z", "level": "ERROR", "logger": "adogent", "message": "Error logging test message", "module": "main", "function": "lifespan", "line": 34, "thread": 281473848987680, "thread_name": "MainThread", "process": 10, "service": "adogent-backend", "environment": "development"}
{"timestamp": "2025-07-06T20:50:14.095384Z", "level": "ERROR", "logger": "adogent", "message": "Error logging test message", "module": "main", "function": "lifespan", "line": 34, "thread": 281473051127840, "thread_name": "MainThread", "process": 11, "service": "adogent-backend", "environment": "development"}
{"timestamp": "2025-07-06T20:50:14.096572Z", "level": "ERROR", "logger": "adogent", "message": "Error logging test message", "module": "main", "function": "lifespan", "line": 34, "thread": 281473603076128, "thread_name": "MainThread", "process": 13, "service": "adogent-backend", "environment": "development"}
{"timestamp": "2025-07-06T20:55:00.840081Z", "level": "ERROR", "logger": "adogent", "message": "Error logging test message", "module": "main", "function": "lifespan", "line": 34, "thread": 281473593077792, "thread_name": "MainThread", "process": 10, "service": "adogent-backend", "environment": "development"}
{"timestamp": "2025-07-06T20:55:00.840218Z", "level": "ERROR", "logger": "adogent", "message": "Error logging test message", "module": "main", "function": "lifespan", "line": 34, "thread": 281473609281568, "thread_name": "MainThread", "process": 12, "service": "adogent-backend", "environment": "development"}
{"timestamp": "2025-07-06T20:55:00.840752Z", "level": "ERROR", "logger": "adogent", "message": "Error logging test message", "module": "main", "function": "lifespan", "line": 34, "thread": 281473393659936, "thread_name": "MainThread", "process": 11, "service": "adogent-backend", "environment": "development"}
{"timestamp": "2025-07-06T20:55:00.841451Z", "level": "ERROR", "logger": "adogent", "message": "Error logging test message", "module": "main", "function": "lifespan", "line": 34, "thread": 281473074548768, "thread_name": "MainThread", "process": 13, "service": "adogent-backend", "environment": "development"}
{"timestamp": "2025-07-06T21:01:59.779589Z", "level": "ERROR", "logger": "adogent", "message": "Error logging test message", "module": "main", "function": "lifespan", "line": 34, "thread": 281473470890016, "thread_name": "MainThread", "process": 14, "service": "adogent-backend", "environment": "development"}
{"timestamp": "2025-07-06T21:01:59.781956Z", "level": "ERROR", "logger": "adogent", "message": "Error logging test message", "module": "main", "function": "lifespan", "line": 34, "thread": 281472956739616, "thread_name": "MainThread", "process": 13, "service": "adogent-backend", "environment": "development"}
{"timestamp": "2025-07-06T21:01:59.782026Z", "level": "ERROR", "logger": "adogent", "message": "Error logging test message", "module": "main", "function": "lifespan", "line": 34, "thread": 281473128108064, "thread_name": "MainThread", "process": 12, "service": "adogent-backend", "environment": "development"}
{"timestamp": "2025-07-06T21:01:59.782057Z", "level": "ERROR", "logger": "adogent", "message": "Error logging test message", "module": "main", "function": "lifespan", "line": 34, "thread": 281473543659552, "thread_name": "MainThread", "process": 11, "service": "adogent-backend", "environment": "development"}
{"timestamp": "2025-07-06T21:38:02.435628Z", "level": "ERROR", "logger": "adogent", "message": "Error logging test message", "module": "main", "function": "lifespan", "line": 34, "thread": 281473044770848, "thread_name": "MainThread", "process": 13, "service": "adogent-backend", "environment": "development"}
{"timestamp": "2025-07-06T21:38:02.435702Z", "level": "ERROR", "logger": "adogent", "message": "Error logging test message", "module": "main", "function": "lifespan", "line": 34, "thread": 281473458774048, "thread_name": "MainThread", "process": 12, "service": "adogent-backend", "environment": "development"}
{"timestamp": "2025-07-06T21:38:02.436740Z", "level": "ERROR", "logger": "adogent", "message": "Error logging test message", "module": "main", "function": "lifespan", "line": 34, "thread": 281472931983392, "thread_name": "MainThread", "process": 10, "service": "adogent-backend", "environment": "development"}
{"timestamp": "2025-07-06T21:38:02.436896Z", "level": "ERROR", "logger": "adogent", "message": "Error logging test message", "module": "main", "function": "lifespan", "line": 34, "thread": 281473538269216, "thread_name": "MainThread", "process": 11, "service": "adogent-backend", "environment": "development"}
{"timestamp": "2025-07-06T21:45:31.024866Z", "level": "ERROR", "logger": "adogent", "message": "Error logging test message", "module": "main", "function": "lifespan", "line": 34, "thread": 281473598431264, "thread_name": "MainThread", "process": 12, "service": "adogent-backend", "environment": "development"}
{"timestamp": "2025-07-06T21:45:31.024894Z", "level": "ERROR", "logger": "adogent", "message": "Error logging test message", "module": "main", "function": "lifespan", "line": 34, "thread": 281473833234464, "thread_name": "MainThread", "process": 10, "service": "adogent-backend", "environment": "development"}
{"timestamp": "2025-07-06T21:45:31.025796Z", "level": "ERROR", "logger": "adogent", "message": "Error logging test message", "module": "main", "function": "lifespan", "line": 34, "thread": 281472917319712, "thread_name": "MainThread", "process": 11, "service": "adogent-backend", "environment": "development"}
{"timestamp": "2025-07-06T21:45:31.026308Z", "level": "ERROR", "logger": "adogent", "message": "Error logging test message", "module": "main", "function": "lifespan", "line": 34, "thread": 281473510440992, "thread_name": "MainThread", "process": 13, "service": "adogent-backend", "environment": "development"}
{"timestamp": "2025-07-06T21:56:55.944532Z", "level": "ERROR", "logger": "adogent", "message": "Error logging test message", "module": "main", "function": "lifespan", "line": 34, "thread": 281473400369184, "thread_name": "MainThread", "process": 10, "service": "adogent-backend", "environment": "development"}
{"timestamp": "2025-07-06T21:56:55.944584Z", "level": "ERROR", "logger": "adogent", "message": "Error logging test message", "module": "main", "function": "lifespan", "line": 34, "thread": 281473321205792, "thread_name": "MainThread", "process": 13, "service": "adogent-backend", "environment": "development"}
{"timestamp": "2025-07-06T21:56:55.944832Z", "level": "ERROR", "logger": "adogent", "message": "Error logging test message", "module": "main", "function": "lifespan", "line": 34, "thread": 281473605750816, "thread_name": "MainThread", "process": 12, "service": "adogent-backend", "environment": "development"}
{"timestamp": "2025-07-06T21:56:55.945731Z", "level": "ERROR", "logger": "adogent", "message": "Error logging test message", "module": "main", "function": "lifespan", "line": 34, "thread": 281473465892896, "thread_name": "MainThread", "process": 11, "service": "adogent-backend", "environment": "development"}
{"timestamp": "2025-07-06T22:11:55.407028Z", "level": "ERROR", "logger": "adogent", "message": "Get AI statistics failed: 'AIService' object has no attribute 'get_agent_statistics'", "module": "ai_routes", "function": "get_ai_statistics", "line": 568, "thread": 281473465892896, "thread_name": "MainThread", "process": 11, "service": "adogent-backend", "environment": "development"}
{"timestamp": "2025-07-06T22:15:21.781287Z", "level": "ERROR", "logger": "adogent", "message": "Chat request failed: 'TokenData' object has no attribute 'id'", "module": "ai_routes", "function": "chat_with_agent", "line": 84, "thread": 281473465892896, "thread_name": "MainThread", "process": 11, "service": "adogent-backend", "environment": "development"}
{"timestamp": "2025-07-06T23:02:58.954967Z", "level": "ERROR", "logger": "adogent", "message": "Error logging test message", "module": "main", "function": "lifespan", "line": 34, "thread": 281472920088608, "thread_name": "MainThread", "process": 10, "service": "adogent-backend", "environment": "development"}
{"timestamp": "2025-07-06T23:02:58.955448Z", "level": "ERROR", "logger": "adogent", "message": "Error logging test message", "module": "main", "function": "lifespan", "line": 34, "thread": 281473679642656, "thread_name": "MainThread", "process": 11, "service": "adogent-backend", "environment": "development"}
{"timestamp": "2025-07-06T23:02:58.956562Z", "level": "ERROR", "logger": "adogent", "message": "Error logging test message", "module": "main", "function": "lifespan", "line": 34, "thread": 281473708372000, "thread_name": "MainThread", "process": 13, "service": "adogent-backend", "environment": "development"}
{"timestamp": "2025-07-06T23:02:58.958129Z", "level": "ERROR", "logger": "adogent", "message": "Error logging test message", "module": "main", "function": "lifespan", "line": 34, "thread": 281472828792864, "thread_name": "MainThread", "process": 12, "service": "adogent-backend", "environment": "development"}
{"timestamp": "2025-07-06T23:03:54.727207Z", "level": "ERROR", "logger": "adogent", "message": "Error logging test message", "module": "main", "function": "lifespan", "line": 34, "thread": 281472901926944, "thread_name": "MainThread", "process": 13, "service": "adogent-backend", "environment": "development"}
{"timestamp": "2025-07-06T23:03:54.727290Z", "level": "ERROR", "logger": "adogent", "message": "Error logging test message", "module": "main", "function": "lifespan", "line": 34, "thread": 281473761390624, "thread_name": "MainThread", "process": 11, "service": "adogent-backend", "environment": "development"}
{"timestamp": "2025-07-06T23:03:54.729766Z", "level": "ERROR", "logger": "adogent", "message": "Error logging test message", "module": "main", "function": "lifespan", "line": 34, "thread": 281473480364064, "thread_name": "MainThread", "process": 12, "service": "adogent-backend", "environment": "development"}
{"timestamp": "2025-07-06T23:03:54.729817Z", "level": "ERROR", "logger": "adogent", "message": "Error logging test message", "module": "main", "function": "lifespan", "line": 34, "thread": 281473767903264, "thread_name": "MainThread", "process": 10, "service": "adogent-backend", "environment": "development"}
{"timestamp": "2025-08-19T14:55:52.224974Z", "level": "ERROR", "logger": "adogent", "message": "Error logging test message", "module": "main", "function": "lifespan", "line": 34, "thread": 281473826840608, "thread_name": "MainThread", "process": 13, "service": "adogent-backend", "environment": "development"}
{"timestamp": "2025-08-19T14:55:52.224976Z", "level": "ERROR", "logger": "adogent", "message": "Error logging test message", "module": "main", "function": "lifespan", "line": 34, "thread": 281473096810528, "thread_name": "MainThread", "process": 11, "service": "adogent-backend", "environment": "development"}
{"timestamp": "2025-08-19T14:55:52.225260Z", "level": "ERROR", "logger": "adogent", "message": "Error logging test message", "module": "main", "function": "lifespan", "line": 34, "thread": 281472833167392, "thread_name": "MainThread", "process": 12, "service": "adogent-backend", "environment": "development"}
